Workbook

Sheet 清单台账
A1: 组件/零件清单下单台账模板（最终版）
A2: 每张订单第一行选择“订单头”，下面填写该订单的组件/零件。复制新订单时复制“订单头+明细行”，粘贴后自动从 1、C001 重新开始。
A3: ERP 后续上传建议读取“ERP导入清单”工作表；清单台账用于日常录入和复制。蓝色列为公式结果，尽量不要手改。
A5: 订单块(自动) | B5: 订单编号 | C5: 制单日期 | D5: 客户名称 | E5: 项目型号 | F5: 行类型 | G5: 自动序号 | H5: 零件类型 | I5: 组件编号(自动) | J5: 所属组件编号(自动/可改) | K5: 物料号 | L5: 图号 | M5: 产品名称 | N5: 展开尺寸 | O5: 厚度 | P5: 订单数 | Q5: 单套用量 | R5: 需求数量(自动) | S5: 单位 | T5: 工艺路线 | U5: 工艺备注 | V5: 图纸日期 | W5: 图纸状态 | X5: helperTopNoInBlock | Y5: helperTopNoForSeq | Z5: helperChildNo | AA5: helperOrderNo | AB5: helperOrderDate | AC5: helperCustomer | AD5: helperProject | AE5: helperExportFlag
A6: =IF($F6="","",COUNTIF($F$6:$F6,"订单头")) -> 1 | B6: RSD-20260510-001 | C6: 46126 | D6: 合肥荣事达太阳能有限公司 | E6: C型15P | F6: 订单头 | G6: =IF($F6="","",IF($F6="订单头","订单头",IF(AND($F6="零件",$J6<>""),IFERROR(SUMIFS($Y$6:$Y$205,$A$6:$A$205,$A6,$I$6:$I$205,$J6)&"."&$Z6,"父组件不存在"),$Y6))) -> 订单头 | I6: =IF($F6="组件","C"&TEXT(COUNTIFS($A$6:$A6,$A6,$F$6:$F6,"组件"),"000"),"") | J6: =IF($F6="零件",IF($P6<>"","",IF(AND($A6=$A5,$F5="组件"),$I5,IF(AND($A6=$A5,$F5="零件",$J5<>""),$J5,""))),"") | R6: =IF(OR($F6="",$F6="订单头"),"",IF(AND($F6="零件",$J6<>""),"",IF($P6="","",$P6*IF($Q6="",1,$Q6)))) | X6: =IF($F6="","",IF($F6="订单头",0,IF(OR($F6="组件",AND($F6="零件",$J6="")),1,0))) -> 0 | Y6: =IF($F6="","",IF($F6="订单头","",IF(AND($F6="零件",$J6<>""),"",$X6))) | Z6: =IF(AND($F6="零件",$J6<>""),COUNTIFS($A$6:$A6,$A6,$J$6:$J6,$J6,$F$6:$F6,"零件"),"") | AA6: =IF($F6="订单头",$B6,"") -> RSD-20260510-001 | AB6: =IF($F6="订单头",$C6,"") -> 46126 | AC6: =IF($F6="订单头",$D6,"") -> 合肥荣事达太阳能有限公司 | AD6: =IF($F6="订单头",$E6,"") -> C型15P | AE6: =IF(OR($F6="组件",$F6="零件"),1,0) -> 0
A7: =IF($F7="","",COUNTIF($F$6:$F7,"订单头")) -> 1 | F7: 零件 | G7: =IF($F7="","",IF($F7="订单头","订单头",IF(AND($F7="零件",$J7<>""),IFERROR(SUMIFS($Y$6:$Y$205,$A$6:$A$205,$A7,$I$6:$I$205,$J7)&"."&$Z7,"父组件不存在"),$Y7))) -> 1 | H7: 通用件 | I7: =IF($F7="组件","C"&TEXT(COUNTIFS($A$6:$A7,$A7,$F$6:$F7,"组件"),"000"),"") | J7: =IF($F7="零件",IF($P7<>"","",IF(AND($A7=$A6,$F6="组件"),$I6,IF(AND($A7=$A6,$F6="零件",$J6<>""),$J6,""))),"") | K7: RS10703010033 | L7: RBKS-300DBII-10-50-01 | M7: 顶盖 | O7: 1mm | P7: 16 | R7: =IF(OR($F7="",$F7="订单头"),"",IF(AND($F7="零件",$J7<>""),IFERROR(SUMIFS($R$6:$R6,$A$6:$A6,$A7,$I$6:$I6,$J7)*IF($Q7="",1,$Q7),""),IF($P7="","",$P7*IF($Q7="",1,$Q7)))) -> 16 | S7: 件 | U7: 百胜样机款 | W7: 旧图 | X7: =IF($F7="","",IF($F7="订单头",0,IF($A7=$A6,$X6,0)+IF(OR($F7="组件",AND($F7="零件",$J7="")),1,0))) -> 1 | Y7: =IF($F7="","",IF($F7="订单头","",IF(AND($F7="零件",$J7<>""),"",$X7))) -> 1 | Z7: =IF(AND($F7="零件",$J7<>""),COUNTIFS($A$6:$A7,$A7,$J$6:$J7,$J7,$F$6:$F7,"零件"),"") | AA7: =IF($F7="","",IF($F7="订单头",$B7,IF($A7=$A6,$AA6,""))) -> RSD-20260510-001 | AB7: =IF($F7="","",IF($F7="订单头",$C7,IF($A7=$A6,$AB6,""))) -> 46126 | AC7: =IF($F7="","",IF($F7="订单头",$D7,IF($A7=$A6,$AC6,""))) -> 合肥荣事达太阳能有限公司 | AD7: =IF($F7="","",IF($F7="订单头",$E7,IF($A7=$A6,$AD6,""))) -> C型15P | AE7: =IF(OR($F7="组件",$F7="零件"),1,0) -> 1
A8: =IF($F8="","",COUNTIF($F$6:$F8,"订单头")) -> 1 | F8: 零件 | G8: =IF($F8="","",IF($F8="订单头","订单头",IF(AND($F8="零件",$J8<>""),IFERROR(SUMIFS($Y$6:$Y$205,$A$6:$A$205,$A8,$I$6:$I$205,$J8)&"."&$Z8,"父组件不存在"),$Y8))) -> 2 | H8: 通用件 | I8: =IF($F8="组件","C"&TEXT(COUNTIFS($A$6:$A8,$A8,$F$6:$F8,"组件"),"000"),"") | J8: =IF($F8="零件",IF($P8<>"","",IF(AND($A8=$A7,$F7="组件"),$I7,IF(AND($A8=$A7,$F7="零件",$J7<>""),$J7,""))),"") | K8: RS10701050458 | L8: RBKS-300DBII-10-01 | M8: 左侧封板 | O8: 1mm | P8: 16 | R8: =IF(OR($F8="",$F8="订单头"),"",IF(AND($F8="零件",$J8<>""),IFERROR(SUMIFS($R$6:$R7,$A$6:$A7,$A8,$I$6:$I7,$J8)*IF($Q8="",1,$Q8),""),IF($P8="","",$P8*IF($Q8="",1,$Q8)))) -> 16 | S8: 件 | T8: 激光切割>折弯 | U8: 百胜样机款 | W8: 旧图 | X8: =IF($F8="","",IF($F8="订单头",0,IF($A8=$A7,$X7,0)+IF(OR($F8="组件",AND($F8="零件",$J8="")),1,0))) -> 2 | Y8: =IF($F8="","",IF($F8="订单头","",IF(AND($F8="零件",$J8<>""),"",$X8))) -> 2 | Z8: =IF(AND($F8="零件",$J8<>""),COUNTIFS($A$6:$A8,$A8,$J$6:$J8,$J8,$F$6:$F8,"零件"),"") | AA8: =IF($F8="","",IF($F8="订单头",$B8,IF($A8=$A7,$AA7,""))) -> RSD-20260510-001 | AB8: =IF($F8="","",IF($F8="订单头",$C8,IF($A8=$A7,$AB7,""))) -> 46126 | AC8: =IF($F8="","",IF($F8="订单头",$D8,IF($A8=$A7,$AC7,""))) -> 合肥荣事达太阳能有限公司 | AD8: =IF($F8="","",IF($F8="订单头",$E8,IF($A8=$A7,$AD7,""))) -> C型15P | AE8: =IF(OR($F8="组件",$F8="零件"),1,0) -> 1
A9: =IF($F9="","",COUNTIF($F$6:$F9,"订单头")) -> 1 | F9: 零件 | G9: =IF($F9="","",IF($F9="订单头","订单头",IF(AND($F9="零件",$J9<>""),IFERROR(SUMIFS($Y$6:$Y$205,$A$6:$A$205,$A9,$I$6:$I$205,$J9)&"."&$Z9,"父组件不存在"),$Y9))) -> 3 | H9: 通用件 | I9: =IF($F9="组件","C"&TEXT(COUNTIFS($A$6:$A9,$A9,$F$6:$F9,"组件"),"000"),"") | J9: =IF($F9="零件",IF($P9<>"","",IF(AND($A9=$A8,$F8="组件"),$I8,IF(AND($A9=$A8,$F8="零件",$J8<>""),$J8,""))),"") | K9: RS10701050459 | L9: RBKS-300DBII-10-03 | M9: 前风机板（钢丝网） | O9: 1mm | P9: 16 | R9: =IF(OR($F9="",$F9="订单头"),"",IF(AND($F9="零件",$J9<>""),IFERROR(SUMIFS($R$6:$R8,$A$6:$A8,$A9,$I$6:$I8,$J9)*IF($Q9="",1,$Q9),""),IF($P9="","",$P9*IF($Q9="",1,$Q9)))) -> 16 | S9: 件 | T9: 激光切割>折弯 | U9: 增冷凝器孔 | V9: 44657 | W9: 旧图 | X9: =IF($F9="","",IF($F9="订单头",0,IF($A9=$A8,$X8,0)+IF(OR($F9="组件",AND($F9="零件",$J9="")),1,0))) -> 3 | Y9: =IF($F9="","",IF($F9="订单头","",IF(AND($F9="零件",$J9<>""),"",$X9))) -> 3 | Z9: =IF(AND($F9="零件",$J9<>""),COUNTIFS($A$6:$A9,$A9,$J$6:$J9,$J9,$F$6:$F9,"零件"),"") | AA9: =IF($F9="","",IF($F9="订单头",$B9,IF($A9=$A8,$AA8,""))) -> RSD-20260510-001 | AB9: =IF($F9="","",IF($F9="订单头",$C9,IF($A9=$A8,$AB8,""))) -> 46126 | AC9: =IF($F9="","",IF($F9="订单头",$D9,IF($A9=$A8,$AC8,""))) -> 合肥荣事达太阳能有限公司 | AD9: =IF($F9="","",IF($F9="订单头",$E9,IF($A9=$A8,$AD8,""))) -> C型15P | AE9: =IF(OR($F9="组件",$F9="零件"),1,0) -> 1
A10: =IF($F10="","",COUNTIF($F$6:$F10,"订单头")) -> 1 | F10: 组件 | G10: =IF($F10="","",IF($F10="订单头","订单头",IF(AND($F10="零件",$J10<>""),IFERROR(SUMIFS($Y$6:$Y$205,$A$6:$A$205,$A10,$I$6:$I$205,$J10)&"."&$Z10,"父组件不存在"),$Y10))) -> 4 | H10: 通用件 | I10: =IF($F10="组件","C"&TEXT(COUNTIFS($A$6:$A10,$A10,$F$6:$F10,"组件"),"000"),"") -> C001 | J10: =IF($F10="零件",IF($P10<>"","",IF(AND($A10=$A9,$F9="组件"),$I9,IF(AND($A10=$A9,$F9="零件",$J9<>""),$J9,""))),"") | K10: RS10701020216 | L10: RBKS-300DBII-10-30 | M10: 风机支架组件 | O10: 2mm | P10: 16 | Q10: 1 | R10: =IF(OR($F10="",$F10="订单头"),"",IF(AND($F10="零件",$J10<>""),IFERROR(SUMIFS($R$6:$R9,$A$6:$A9,$A10,$I$6:$I9,$J10)*IF($Q10="",1,$Q10),""),IF($P10="","",$P10*IF($Q10="",1,$Q10)))) -> 16 | S10: 套 | T10: 装配 | U10: 螺丝组装，百胜样机款 | W10: 旧图 | X10: =IF($F10="","",IF($F10="订单头",0,IF($A10=$A9,$X9,0)+IF(OR($F10="组件",AND($F10="零件",$J10="")),1,0))) -> 4 | Y10: =IF($F10="","",IF($F10="订单头","",IF(AND($F10="零件",$J10<>""),"",$X10))) -> 4 | Z10: =IF(AND($F10="零件",$J10<>""),COUNTIFS($A$6:$A10,$A10,$J$6:$J10,$J10,$F$6:$F10,"零件"),"") | AA10: =IF($F10="","",IF($F10="订单头",$B10,IF($A10=$A9,$AA9,""))) -> RSD-20260510-001 | AB10: =IF($F10="","",IF($F10="订单头",$C10,IF($A10=$A9,$AB9,""))) -> 46126 | AC10: =IF($F10="","",IF($F10="订单头",$D10,IF($A10=$A9,$AC9,""))) -> 合肥荣事达太阳能有限公司 | AD10: =IF($F10="","",IF($F10="订单头",$E10,IF($A10=$A9,$AD9,""))) -> C型15P | AE10: =IF(OR($F10="组件",$F10="零件"),1,0) -> 1
A11: =IF($F11="","",COUNTIF($F$6:$F11,"订单头")) -> 1 | F11: 零件 | G11: =IF($F11="","",IF($F11="订单头","订单头",IF(AND($F11="零件",$J11<>""),IFERROR(SUMIFS($Y$6:$Y$205,$A$6:$A$205,$A11,$I$6:$I$205,$J11)&"."&$Z11,"父组件不存在"),$Y11))) -> 4.1 | H11: 通用件 | I11: =IF($F11="组件","C"&TEXT(COUNTIFS($A$6:$A11,$A11,$F$6:$F11,"组件"),"000"),"") | J11: =IF($F11="零件",IF($P11<>"","",IF(AND($A11=$A10,$F10="组件"),$I10,IF(AND($A11=$A10,$F10="零件",$J10<>""),$J10,""))),"") -> C001 | L11: RLKS-300DBII-10-30-B | M11: 风机支架折弯件 | O11: 2mm | Q11: 1 | R11: =IF(OR($F11="",$F11="订单头"),"",IF(AND($F11="零件",$J11<>""),IFERROR(SUMIFS($R$6:$R10,$A$6:$A10,$A11,$I$6:$I10,$J11)*IF($Q11="",1,$Q11),""),IF($P11="","",$P11*IF($Q11="",1,$Q11)))) -> 16 | S11: 件 | T11: 激光切割>折弯 | U11: 组件 C001 的子件 | W11: 旧图 | X11: =IF($F11="","",IF($F11="订单头",0,IF($A11=$A10,$X10,0)+IF(OR($F11="组件",AND($F11="零件",$J11="")),1,0))) -> 4 | Y11: =IF($F11="","",IF($F11="订单头","",IF(AND($F11="零件",$J11<>""),"",$X11))) | Z11: =IF(AND($F11="零件",$J11<>""),COUNTIFS($A$6:$A11,$A11,$J$6:$J11,$J11,$F$6:$F11,"零件"),"") -> 1 | AA11: =IF($F11="","",IF($F11="订单头",$B11,IF($A11=$A10,$AA10,""))) -> RSD-20260510-001 | AB11: =IF($F11="","",IF($F11="订单头",$C11,IF($A11=$A10,$AB10,""))) -> 46126 | AC11: =IF($F11="","",IF($F11="订单头",$D11,IF($A11=$A10,$AC10,""))) -> 合肥荣事达太阳能有限公司 | AD11: =IF($F11="","",IF($F11="订单头",$E11,IF($A11=$A10,$AD10,""))) -> C型15P | AE11: =IF(OR($F11="组件",$F11="零件"),1,0) -> 1
A12: =IF($F12="","",COUNTIF($F$6:$F12,"订单头")) -> 1 | F12: 零件 | G12: =IF($F12="","",IF($F12="订单头","订单头",IF(AND($F12="零件",$J12<>""),IFERROR(SUMIFS($Y$6:$Y$205,$A$6:$A$205,$A12,$I$6:$I$205,$J12)&"."&$Z12,"父组件不存在"),$Y12))) -> 4.2 | H12: 通用件 | I12: =IF($F12="组件","C"&TEXT(COUNTIFS($A$6:$A12,$A12,$F$6:$F12,"组件"),"000"),"") | J12: =IF($F12="零件",IF($P12<>"","",IF(AND($A12=$A11,$F11="组件"),$I11,IF(AND($A12=$A11,$F11="零件",$J11<>""),$J11,""))),"") -> C001 | L12: RBKS-300DBII-10-30-05 | M12: 机架加强板 | O12: 1mm | Q12: 1 | R12: =IF(OR($F12="",$F12="订单头"),"",IF(AND($F12="零件",$J12<>""),IFERROR(SUMIFS($R$6:$R11,$A$6:$A11,$A12,$I$6:$I11,$J12)*IF($Q12="",1,$Q12),""),IF($P12="","",$P12*IF($Q12="",1,$Q12)))) -> 16 | S12: 件 | T12: 激光切割 | U12: 模具成型，百胜样机款 | W12: 旧图 | X12: =IF($F12="","",IF($F12="订单头",0,IF($A12=$A11,$X11,0)+IF(OR($F12="组件",AND($F12="零件",$J12="")),1,0))) -> 4 | Y12: =IF($F12="","",IF($F12="订单头","",IF(AND($F12="零件",$J12<>""),"",$X12))) | Z12: =IF(AND($F12="零件",$J12<>""),COUNTIFS($A$6:$A12,$A12,$J$6:$J12,$J12,$F$6:$F12,"零件"),"") -> 2 | AA12: =IF($F12="","",IF($F12="订单头",$B12,IF($A12=$A11,$AA11,""))) -> RSD-20260510-001 | AB12: =IF($F12="","",IF($F12="订单头",$C12,IF($A12=$A11,$AB11,""))) -> 46126 | AC12: =IF($F12="","",IF($F12="订单头",$D12,IF($A12=$A11,$AC11,""))) -> 合肥荣事达太阳能有限公司 | AD12: =IF($F12="","",IF($F12="订单头",$E12,IF($A12=$A11,$AD11,""))) -> C型15P | AE12: =IF(OR($F12="组件",$F12="零件"),1,0) -> 1
A13: =IF($F13="","",COUNTIF($F$6:$F13,"订单头")) -> 1 | F13: 组件 | G13: =IF($F13="","",IF($F13="订单头","订单头",IF(AND($F13="零件",$J13<>""),IFERROR(SUMIFS($Y$6:$Y$205,$A$6:$A$205,$A13,$I$6:$I$205,$J13)&"."&$Z13,"父组件不存在"),$Y13))) -> 5 | H13: 定制件 | I13: =IF($F13="组件","C"&TEXT(COUNTIFS($A$6:$A13,$A13,$F$6:$F13,"组件"),"000"),"") -> C002 | J13: =IF($F13="零件",IF($P13<>"","",IF(AND($A13=$A12,$F12="组件"),$I12,IF(AND($A13=$A12,$F12="零件",$J12<>""),$J12,""))),"") | K13: RS10701010142 | L13: RBKS-300DBII-10-00 | M13: 底盘组件（激光割） | O13: 2mm | P13: 16 | Q13: 1 | R13: =IF(OR($F13="",$F13="订单头"),"",IF(AND($F13="零件",$J13<>""),IFERROR(SUMIFS($R$6:$R12,$A$6:$A12,$A13,$I$6:$I12,$J13)*IF($Q13="",1,$Q13),""),IF($P13="","",$P13*IF($Q13="",1,$Q13)))) -> 16 | S13: 套 | T13: 激光切割>焊接>装配 | U13: 点5个电热丝固定卡，割孔，焊螺丝 | V13: 45247 | W13: 旧图 | X13: =IF($F13="","",IF($F13="订单头",0,IF($A13=$A12,$X12,0)+IF(OR($F13="组件",AND($F13="零件",$J13="")),1,0))) -> 5 | Y13: =IF($F13="","",IF($F13="订单头","",IF(AND($F13="零件",$J13<>""),"",$X13))) -> 5 | Z13: =IF(AND($F13="零件",$J13<>""),COUNTIFS($A$6:$A13,$A13,$J$6:$J13,$J13,$F$6:$F13,"零件"),"") | AA13: =IF($F13="","",IF($F13="订单头",$B13,IF($A13=$A12,$AA12,""))) -> RSD-20260510-001 | AB13: =IF($F13="","",IF($F13="订单头",$C13,IF($A13=$A12,$AB12,""))) -> 46126 | AC13: =IF($F13="","",IF($F13="订单头",$D13,IF($A13=$A12,$AC12,""))) -> 合肥荣事达太阳能有限公司 | AD13: =IF($F13="","",IF($F13="订单头",$E13,IF($A13=$A12,$AD12,""))) -> C型15P | AE13: =IF(OR($F13="组件",$F13="零件"),1,0) -> 1
A14: =IF($F14="","",COUNTIF($F$6:$F14,"订单头")) -> 1 | F14: 零件 | G14: =IF($F14="","",IF($F14="订单头","订单头",IF(AND($F14="零件",$J14<>""),IFERROR(SUMIFS($Y$6:$Y$205,$A$6:$A$205,$A14,$I$6:$I$205,$J14)&"."&$Z14,"父组件不存在"),$Y14))) -> 5.1 | H14: 定制件 | I14: =IF($F14="组件","C"&TEXT(COUNTIFS($A$6:$A14,$A14,$F$6:$F14,"组件"),"000"),"") | J14: =IF($F14="零件",IF($P14<>"","",IF(AND($A14=$A13,$F13="组件"),$I13,IF(AND($A14=$A13,$F13="零件",$J13<>""),$J13,""))),"") -> C002 | L14: RBKS-300DBII-10-00-A | M14: 底盘板 | O14: 2mm | Q14: 1 | R14: =IF(OR($F14="",$F14="订单头"),"",IF(AND($F14="零件",$J14<>""),IFERROR(SUMIFS($R$6:$R13,$A$6:$A13,$A14,$I$6:$I13,$J14)*IF($Q14="",1,$Q14),""),IF($P14="","",$P14*IF($Q14="",1,$Q14)))) -> 16 | S14: 件 | T14: 激光切割 | U14: 小孔，割3-Φ3.2孔 | W14: 待确认 | X14: =IF($F14="","",IF($F14="订单头",0,IF($A14=$A13,$X13,0)+IF(OR($F14="组件",AND($F14="零件",$J14="")),1,0))) -> 5 | Y14: =IF($F14="","",IF($F14="订单头","",IF(AND($F14="零件",$J14<>""),"",$X14))) | Z14: =IF(AND($F14="零件",$J14<>""),COUNTIFS($A$6:$A14,$A14,$J$6:$J14,$J14,$F$6:$F14,"零件"),"") -> 1 | AA14: =IF($F14="","",IF($F14="订单头",$B14,IF($A14=$A13,$AA13,""))) -> RSD-20260510-001 | AB14: =IF($F14="","",IF($F14="订单头",$C14,IF($A14=$A13,$AB13,""))) -> 46126 | AC14: =IF($F14="","",IF($F14="订单头",$D14,IF($A14=$A13,$AC13,""))) -> 合肥荣事达太阳能有限公司 | AD14: =IF($F14="","",IF($F14="订单头",$E14,IF($A14=$A13,$AD13,""))) -> C型15P | AE14: =IF(OR($F14="组件",$F14="零件"),1,0) -> 1
A15: =IF($F15="","",COUNTIF($F$6:$F15,"订单头")) -> 1 | F15: 零件 | G15: =IF($F15="","",IF($F15="订单头","订单头",IF(AND($F15="零件",$J15<>""),IFERROR(SUMIFS($Y$6:$Y$205,$A$6:$A$205,$A15,$I$6:$I$205,$J15)&"."&$Z15,"父组件不存在"),$Y15))) -> 5.2 | H15: 定制件 | I15: =IF($F15="组件","C"&TEXT(COUNTIFS($A$6:$A15,$A15,$F$6:$F15,"组件"),"000"),"") | J15: =IF($F15="零件",IF($P15<>"","",IF(AND($A15=$A14,$F14="组件"),$I14,IF(AND($A15=$A14,$F14="零件",$J14<>""),$J14,""))),"") -> C002 | L15: RBKS-300DBII-10-00-B | M15: 底盘加强片 | O15: 1.5mm | Q15: 1 | R15: =IF(OR($F15="",$F15="订单头"),"",IF(AND($F15="零件",$J15<>""),IFERROR(SUMIFS($R$6:$R14,$A$6:$A14,$A15,$I$6:$I14,$J15)*IF($Q15="",1,$Q15),""),IF($P15="","",$P15*IF($Q15="",1,$Q15)))) -> 16 | S15: 件 | T15: 激光切割>折弯 | U15: 焊2-M8x20螺丝 | W15: 待确认 | X15: =IF($F15="","",IF($F15="订单头",0,IF($A15=$A14,$X14,0)+IF(OR($F15="组件",AND($F15="零件",$J15="")),1,0))) -> 5 | Y15: =IF($F15="","",IF($F15="订单头","",IF(AND($F15="零件",$J15<>""),"",$X15))) | Z15: =IF(AND($F15="零件",$J15<>""),COUNTIFS($A$6:$A15,$A15,$J$6:$J15,$J15,$F$6:$F15,"零件"),"") -> 2 | AA15: =IF($F15="","",IF($F15="订单头",$B15,IF($A15=$A14,$AA14,""))) -> RSD-20260510-001 | AB15: =IF($F15="","",IF($F15="订单头",$C15,IF($A15=$A14,$AB14,""))) -> 46126 | AC15: =IF($F15="","",IF($F15="订单头",$D15,IF($A15=$A14,$AC14,""))) -> 合肥荣事达太阳能有限公司 | AD15: =IF($F15="","",IF($F15="订单头",$E15,IF($A15=$A14,$AD14,""))) -> C型15P | AE15: =IF(OR($F15="组件",$F15="零件"),1,0) -> 1
A16: =IF($F16="","",COUNTIF($F$6:$F16,"订单头")) -> 1 | F16: 零件 | G16: =IF($F16="","",IF($F16="订单头","订单头",IF(AND($F16="零件",$J16<>""),IFERROR(SUMIFS($Y$6:$Y$205,$A$6:$A$205,$A16,$I$6:$I$205,$J16)&"."&$Z16,"父组件不存在"),$Y16))) -> 6 | H16: 外协件 | I16: =IF($F16="组件","C"&TEXT(COUNTIFS($A$6:$A16,$A16,$F$6:$F16,"组件"),"000"),"") | J16: =IF($F16="零件",IF($P16<>"","",IF(AND($A16=$A15,$F15="组件"),$I15,IF(AND($A16=$A15,$F15="零件",$J15<>""),$J15,""))),"") | K16: RS10707010049 | L16: RBKS-300DBII-10-04 | M16: 网罩 | P16: 32 | R16: =IF(OR($F16="",$F16="订单头"),"",IF(AND($F16="零件",$J16<>""),IFERROR(SUMIFS($R$6:$R15,$A$6:$A15,$A16,$I$6:$I15,$J16)*IF($Q16="",1,$Q16),""),IF($P16="","",$P16*IF($Q16="",1,$Q16)))) -> 32 | S16: 件 | U16: 钢丝网 | W16: 旧图 | X16: =IF($F16="","",IF($F16="订单头",0,IF($A16=$A15,$X15,0)+IF(OR($F16="组件",AND($F16="零件",$J16="")),1,0))) -> 6 | Y16: =IF($F16="","",IF($F16="订单头","",IF(AND($F16="零件",$J16<>""),"",$X16))) -> 6 | Z16: =IF(AND($F16="零件",$J16<>""),COUNTIFS($A$6:$A16,$A16,$J$6:$J16,$J16,$F$6:$F16,"零件"),"") | AA16: =IF($F16="","",IF($F16="订单头",$B16,IF($A16=$A15,$AA15,""))) -> RSD-20260510-001 | AB16: =IF($F16="","",IF($F16="订单头",$C16,IF($A16=$A15,$AB15,""))) -> 46126 | AC16: =IF($F16="","",IF($F16="订单头",$D16,IF($A16=$A15,$AC15,""))) -> 合肥荣事达太阳能有限公司 | AD16: =IF($F16="","",IF($F16="订单头",$E16,IF($A16=$A15,$AD15,""))) -> C型15P | AE16: =IF(OR($F16="组件",$F16="零件"),1,0) -> 1
A17: =IF($F17="","",COUNTIF($F$6:$F17,"订单头")) | G17: =IF($F17="","",IF($F17="订单头","订单头",IF(AND($F17="零件",$J17<>""),IFERROR(SUMIFS($Y$6:$Y$205,$A$6:$A$205,$A17,$I$6:$I$205,$J17)&"."&$Z17,"父组件不存在"),$Y17))) | I17: =IF($F17="组件","C"&TEXT(COUNTIFS($A$6:$A17,$A17,$F$6:$F17,"组件"),"000"),"") | J17: =IF($F17="零件",IF($P17<>"","",IF(AND($A17=$A16,$F16="组件"),$I16,IF(AND($A17=$A16,$F16="零件",$J16<>""),$J16,""))),"") | R17: =IF(OR($F17="",$F17="订单头"),"",IF(AND($F17="零件",$J17<>""),IFERROR(SUMIFS($R$6:$R16,$A$6:$A16,$A17,$I$6:$I16,$J17)*IF($Q17="",1,$Q17),""),IF($P17="","",$P17*IF($Q17="",1,$Q17)))) | X17: =IF($F17="","",IF($F17="订单头",0,IF($A17=$A16,$X16,0)+IF(OR($F17="组件",AND($F17="零件",$J17="")),1,0))) | Y17: =IF($F17="","",IF($F17="订单头","",IF(AND($F17="零件",$J17<>""),"",$X17))) | Z17: =IF(AND($F17="零件",$J17<>""),COUNTIFS($A$6:$A17,$A17,$J$6:$J17,$J17,$F$6:$F17,"零件"),"") | AA17: =IF($F17="","",IF($F17="订单头",$B17,IF($A17=$A16,$AA16,""))) | AB17: =IF($F17="","",IF($F17="订单头",$C17,IF($A17=$A16,$AB16,""))) | AC17: =IF($F17="","",IF($F17="订单头",$D17,IF($A17=$A16,$AC16,""))) | AD17: =IF($F17="","",IF($F17="订单头",$E17,IF($A17=$A16,$AD16,""))) | AE17: =IF(OR($F17="组件",$F17="零件"),1,0) -> 0
A18: =IF($F18="","",COUNTIF($F$6:$F18,"订单头")) -> 2 | B18: RSD-20260601-002 | C18: 46174 | D18: 合肥荣事达太阳能有限公司 | E18: B型5P | F18: 订单头 | G18: =IF($F18="","",IF($F18="订单头","订单头",IF(AND($F18="零件",$J18<>""),IFERROR(SUMIFS($Y$6:$Y$205,$A$6:$A$205,$A18,$I$6:$I$205,$J18)&"."&$Z18,"父组件不存在"),$Y18))) -> 订单头 | I18: =IF($F18="组件","C"&TEXT(COUNTIFS($A$6:$A18,$A18,$F$6:$F18,"组件"),"000"),"") | J18: =IF($F18="零件",IF($P18<>"","",IF(AND($A18=$A17,$F17="组件"),$I17,IF(AND($A18=$A17,$F17="零件",$J17<>""),$J17,""))),"") | R18: =IF(OR($F18="",$F18="订单头"),"",IF(AND($F18="零件",$J18<>""),IFERROR(SUMIFS($R$6:$R17,$A$6:$A17,$A18,$I$6:$I17,$J18)*IF($Q18="",1,$Q18),""),IF($P18="","",$P18*IF($Q18="",1,$Q18)))) | X18: =IF($F18="","",IF($F18="订单头",0,IF($A18=$A17,$X17,0)+IF(OR($F18="组件",AND($F18="零件",$J18="")),1,0))) -> 0 | Y18: =IF($F18="","",IF($F18="订单头","",IF(AND($F18="零件",$J18<>""),"",$X18))) | Z18: =IF(AND($F18="零件",$J18<>""),COUNTIFS($A$6:$A18,$A18,$J$6:$J18,$J18,$F$6:$F18,"零件"),"") | AA18: =IF($F18="","",IF($F18="订单头",$B18,IF($A18=$A17,$AA17,""))) -> RSD-20260601-002 | AB18: =IF($F18="","",IF($F18="订单头",$C18,IF($A18=$A17,$AB17,""))) -> 46174 | AC18: =IF($F18="","",IF($F18="订单头",$D18,IF($A18=$A17,$AC17,""))) -> 合肥荣事达太阳能有限公司 | AD18: =IF($F18="","",IF($F18="订单头",$E18,IF($A18=$A17,$AD17,""))) -> B型5P | AE18: =IF(OR($F18="组件",$F18="零件"),1,0) -> 0
A19: =IF($F19="","",COUNTIF($F$6:$F19,"订单头")) -> 2 | F19: 零件 | G19: =IF($F19="","",IF($F19="订单头","订单头",IF(AND($F19="零件",$J19<>""),IFERROR(SUMIFS($Y$6:$Y$205,$A$6:$A$205,$A19,$I$6:$I$205,$J19)&"."&$Z19,"父组件不存在"),$Y19))) -> 1 | H19: 通用件 | I19: =IF($F19="组件","C"&TEXT(COUNTIFS($A$6:$A19,$A19,$F$6:$F19,"组件"),"000"),"") | J19: =IF($F19="零件",IF($P19<>"","",IF(AND($A19=$A18,$F18="组件"),$I18,IF(AND($A19=$A18,$F18="零件",$J18<>""),$J18,""))),"") | K19: RS10703222 | L19: B5机型物料号-10-50-01 | M19: 顶盖 | O19: 1mm | P19: 16 | R19: =IF(OR($F19="",$F19="订单头"),"",IF(AND($F19="零件",$J19<>""),IFERROR(SUMIFS($R$6:$R18,$A$6:$A18,$A19,$I$6:$I18,$J19)*IF($Q19="",1,$Q19),""),IF($P19="","",$P19*IF($Q19="",1,$Q19)))) -> 16 | S19: 件 | U19: 百胜样机款 | W19: 旧图 | X19: =IF($F19="","",IF($F19="订单头",0,IF($A19=$A18,$X18,0)+IF(OR($F19="组件",AND($F19="零件",$J19="")),1,0))) -> 1 | Y19: =IF($F19="","",IF($F19="订单头","",IF(AND($F19="零件",$J19<>""),"",$X19))) -> 1 | Z19: =IF(AND($F19="零件",$J19<>""),COUNTIFS($A$6:$A19,$A19,$J$6:$J19,$J19,$F$6:$F19,"零件"),"") | AA19: =IF($F19="","",IF($F19="订单头",$B19,IF($A19=$A18,$AA18,""))) -> RSD-20260601-002 | AB19: =IF($F19="","",IF($F19="订单头",$C19,IF($A19=$A18,$AB18,""))) -> 46174 | AC19: =IF($F19="","",IF($F19="订单头",$D19,IF($A19=$A18,$AC18,""))) -> 合肥荣事达太阳能有限公司 | AD19: =IF($F19="","",IF($F19="订单头",$E19,IF($A19=$A18,$AD18,""))) -> B型5P | AE19: =IF(OR($F19="组件",$F19="零件"),1,0) -> 1
A20: =IF($F20="","",COUNTIF($F$6:$F20,"订单头")) -> 2 | F20: 零件 | G20: =IF($F20="","",IF($F20="订单头","订单头",IF(AND($F20="零件",$J20<>""),IFERROR(SUMIFS($Y$6:$Y$205,$A$6:$A$205,$A20,$I$6:$I$205,$J20)&"."&$Z20,"父组件不存在"),$Y20))) -> 2 | H20: 通用件 | I20: =IF($F20="组件","C"&TEXT(COUNTIFS($A$6:$A20,$A20,$F$6:$F20,"组件"),"000"),"") | J20: =IF($F20="零件",IF($P20<>"","",IF(AND($A20=$A19,$F19="组件"),$I19,IF(AND($A20=$A19,$F19="零件",$J19<>""),$J19,""))),"") | K20: RS1070103 | L20: B5机型物料号-10-01 | M20: 左侧封板 | O20: 1mm | P20: 16 | R20: =IF(OR($F20="",$F20="订单头"),"",IF(AND($F20="零件",$J20<>""),IFERROR(SUMIFS($R$6:$R19,$A$6:$A19,$A20,$I$6:$I19,$J20)*IF($Q20="",1,$Q20),""),IF($P20="","",$P20*IF($Q20="",1,$Q20)))) -> 16 | S20: 件 | T20: 激光切割>折弯 | U20: 百胜样机款 | W20: 旧图 | X20: =IF($F20="","",IF($F20="订单头",0,IF($A20=$A19,$X19,0)+IF(OR($F20="组件",AND($F20="零件",$J20="")),1,0))) -> 2 | Y20: =IF($F20="","",IF($F20="订单头","",IF(AND($F20="零件",$J20<>""),"",$X20))) -> 2 | Z20: =IF(AND($F20="零件",$J20<>""),COUNTIFS($A$6:$A20,$A20,$J$6:$J20,$J20,$F$6:$F20,"零件"),"") | AA20: =IF($F20="","",IF($F20="订单头",$B20,IF($A20=$A19,$AA19,""))) -> RSD-20260601-002 | AB20: =IF($F20="","",IF($F20="订单头",$C20,IF($A20=$A19,$AB19,""))) -> 46174 | AC20: =IF($F20="","",IF($F20="订单头",$D20,IF($A20=$A19,$AC19,""))) -> 合肥荣事达太阳能有限公司 | AD20: =IF($F20="","",IF($F20="订单头",$E20,IF($A20=$A19,$AD19,""))) -> B型5P | AE20: =IF(OR($F20="组件",$F20="零件"),1,0) -> 1
A21: =IF($F21="","",COUNTIF($F$6:$F21,"订单头")) -> 2 | F21: 组件 | G21: =IF($F21="","",IF($F21="订单头","订单头",IF(AND($F21="零件",$J21<>""),IFERROR(SUMIFS($Y$6:$Y$205,$A$6:$A$205,$A21,$I$6:$I$205,$J21)&"."&$Z21,"父组件不存在"),$Y21))) -> 3 | H21: 通用件 | I21: =IF($F21="组件","C"&TEXT(COUNTIFS($A$6:$A21,$A21,$F$6:$F21,"组件"),"000"),"") -> C001 | J21: =IF($F21="零件",IF($P21<>"","",IF(AND($A21=$A20,$F20="组件"),$I20,IF(AND($A21=$A20,$F20="零件",$J20<>""),$J20,""))),"") | K21: RS1071123 | L21: B5机型物料号-10-30 | M21: 风机支架组件 | O21: 2mm | P21: 90 | Q21: 2 | R21: =IF(OR($F21="",$F21="订单头"),"",IF(AND($F21="零件",$J21<>""),IFERROR(SUMIFS($R$6:$R20,$A$6:$A20,$A21,$I$6:$I20,$J21)*IF($Q21="",1,$Q21),""),IF($P21="","",$P21*IF($Q21="",1,$Q21)))) -> 180 | S21: 套 | T21: 装配 | U21: 组件本体 90 套，每套用 2 件 | W21: 旧图 | X21: =IF($F21="","",IF($F21="订单头",0,IF($A21=$A20,$X20,0)+IF(OR($F21="组件",AND($F21="零件",$J21="")),1,0))) -> 3 | Y21: =IF($F21="","",IF($F21="订单头","",IF(AND($F21="零件",$J21<>""),"",$X21))) -> 3 | Z21: =IF(AND($F21="零件",$J21<>""),COUNTIFS($A$6:$A21,$A21,$J$6:$J21,$J21,$F$6:$F21,"零件"),"") | AA21: =IF($F21="","",IF($F21="订单头",$B21,IF($A21=$A20,$AA20,""))) -> RSD-20260601-002 | AB21: =IF($F21="","",IF($F21="订单头",$C21,IF($A21=$A20,$AB20,""))) -> 46174 | AC21: =IF($F21="","",IF($F21="订单头",$D21,IF($A21=$A20,$AC20,""))) -> 合肥荣事达太阳能有限公司 | AD21: =IF($F21="","",IF($F21="订单头",$E21,IF($A21=$A20,$AD20,""))) -> B型5P | AE21: =IF(OR($F21="组件",$F21="零件"),1,0) -> 1
A22: =IF($F22="","",COUNTIF($F$6:$F22,"订单头")) -> 2 | F22: 零件 | G22: =IF($F22="","",IF($F22="订单头","订单头",IF(AND($F22="零件",$J22<>""),IFERROR(SUMIFS($Y$6:$Y$205,$A$6:$A$205,$A22,$I$6:$I$205,$J22)&"."&$Z22,"父组件不存在"),$Y22))) -> 3.1 | H22: 通用件 | I22: =IF($F22="组件","C"&TEXT(COUNTIFS($A$6:$A22,$A22,$F$6:$F22,"组件"),"000"),"") | J22: =IF($F22="零件",IF($P22<>"","",IF(AND($A22=$A21,$F21="组件"),$I21,IF(AND($A22=$A21,$F21="零件",$J21<>""),$J21,""))),"") -> C001 | L22: B5机型物料号-10-30-B | M22: 风机支架折弯件 | O22: 2mm | Q22: 2 | R22: =IF(OR($F22="",$F22="订单头"),"",IF(AND($F22="零件",$J22<>""),IFERROR(SUMIFS($R$6:$R21,$A$6:$A21,$A22,$I$6:$I21,$J22)*IF($Q22="",1,$Q22),""),IF($P22="","",$P22*IF($Q22="",1,$Q22)))) -> 360 | S22: 件 | T22: 激光切割>折弯 | U22: 按父组件需求数量×2 | W22: 旧图 | X22: =IF($F22="","",IF($F22="订单头",0,IF($A22=$A21,$X21,0)+IF(OR($F22="组件",AND($F22="零件",$J22="")),1,0))) -> 3 | Y22: =IF($F22="","",IF($F22="订单头","",IF(AND($F22="零件",$J22<>""),"",$X22))) | Z22: =IF(AND($F22="零件",$J22<>""),COUNTIFS($A$6:$A22,$A22,$J$6:$J22,$J22,$F$6:$F22,"零件"),"") -> 1 | AA22: =IF($F22="","",IF($F22="订单头",$B22,IF($A22=$A21,$AA21,""))) -> RSD-20260601-002 | AB22: =IF($F22="","",IF($F22="订单头",$C22,IF($A22=$A21,$AB21,""))) -> 46174 | AC22: =IF($F22="","",IF($F22="订单头",$D22,IF($A22=$A21,$AC21,""))) -> 合肥荣事达太阳能有限公司 | AD22: =IF($F22="","",IF($F22="订单头",$E22,IF($A22=$A21,$AD21,""))) -> B型5P | AE22: =IF(OR($F22="组件",$F22="零件"),1,0) -> 1
A23: =IF($F23="","",COUNTIF($F$6:$F23,"订单头")) -> 2 | F23: 零件 | G23: =IF($F23="","",IF($F23="订单头","订单头",IF(AND($F23="零件",$J23<>""),IFERROR(SUMIFS($Y$6:$Y$205,$A$6:$A$205,$A23,$I$6:$I$205,$J23)&"."&$Z23,"父组件不存在"),$Y23))) -> 3.2 | H23: 通用件 | I23: =IF($F23="组件","C"&TEXT(COUNTIFS($A$6:$A23,$A23,$F$6:$F23,"组件"),"000"),"") | J23: =IF($F23="零件",IF($P23<>"","",IF(AND($A23=$A22,$F22="组件"),$I22,IF(AND($A23=$A22,$F22="零件",$J22<>""),$J22,""))),"") -> C001 | L23: B5机型物料号-10-30-05 | M23: 机架加强板 | O23: 1mm | Q23: 1 | R23: =IF(OR($F23="",$F23="订单头"),"",IF(AND($F23="零件",$J23<>""),IFERROR(SUMIFS($R$6:$R22,$A$6:$A22,$A23,$I$6:$I22,$J23)*IF($Q23="",1,$Q23),""),IF($P23="","",$P23*IF($Q23="",1,$Q23)))) -> 180 | S23: 件 | T23: 激光切割 | U23: 按父组件需求数量×1 | W23: 旧图 | X23: =IF($F23="","",IF($F23="订单头",0,IF($A23=$A22,$X22,0)+IF(OR($F23="组件",AND($F23="零件",$J23="")),1,0))) -> 3 | Y23: =IF($F23="","",IF($F23="订单头","",IF(AND($F23="零件",$J23<>""),"",$X23))) | Z23: =IF(AND($F23="零件",$J23<>""),COUNTIFS($A$6:$A23,$A23,$J$6:$J23,$J23,$F$6:$F23,"零件"),"") -> 2 | AA23: =IF($F23="","",IF($F23="订单头",$B23,IF($A23=$A22,$AA22,""))) -> RSD-20260601-002 | AB23: =IF($F23="","",IF($F23="订单头",$C23,IF($A23=$A22,$AB22,""))) -> 46174 | AC23: =IF($F23="","",IF($F23="订单头",$D23,IF($A23=$A22,$AC22,""))) -> 合肥荣事达太阳能有限公司 | AD23: =IF($F23="","",IF($F23="订单头",$E23,IF($A23=$A22,$AD22,""))) -> B型5P | AE23: =IF(OR($F23="组件",$F23="零件"),1,0) -> 1
A24: =IF($F24="","",COUNTIF($F$6:$F24,"订单头")) -> 2 | F24: 组件 | G24: =IF($F24="","",IF($F24="订单头","订单头",IF(AND($F24="零件",$J24<>""),IFERROR(SUMIFS($Y$6:$Y$205,$A$6:$A$205,$A24,$I$6:$I$205,$J24)&"."&$Z24,"父组件不存在"),$Y24))) -> 4 | H24: 定制件 | I24: =IF($F24="组件","C"&TEXT(COUNTIFS($A$6:$A24,$A24,$F$6:$F24,"组件"),"000"),"") -> C002 | J24: =IF($F24="零件",IF($P24<>"","",IF(AND($A24=$A23,$F23="组件"),$I23,IF(AND($A24=$A23,$F23="零件",$J23<>""),$J23,""))),"") | K24: RS103 | L24: B5机型物料号-10-00 | M24: 底盘组件（激光割） | O24: 2mm | P24: 16 | Q24: 1 | R24: =IF(OR($F24="",$F24="订单头"),"",IF(AND($F24="零件",$J24<>""),IFERROR(SUMIFS($R$6:$R23,$A$6:$A23,$A24,$I$6:$I23,$J24)*IF($Q24="",1,$Q24),""),IF($P24="","",$P24*IF($Q24="",1,$Q24)))) -> 16 | S24: 套 | T24: 激光切割>焊接>装配 | U24: 点5个电热丝固定卡，割孔，焊螺丝 | V24: 45247 | W24: 旧图 | X24: =IF($F24="","",IF($F24="订单头",0,IF($A24=$A23,$X23,0)+IF(OR($F24="组件",AND($F24="零件",$J24="")),1,0))) -> 4 | Y24: =IF($F24="","",IF($F24="订单头","",IF(AND($F24="零件",$J24<>""),"",$X24))) -> 4 | Z24: =IF(AND($F24="零件",$J24<>""),COUNTIFS($A$6:$A24,$A24,$J$6:$J24,$J24,$F$6:$F24,"零件"),"") | AA24: =IF($F24="","",IF($F24="订单头",$B24,IF($A24=$A23,$AA23,""))) -> RSD-20260601-002 | AB24: =IF($F24="","",IF($F24="订单头",$C24,IF($A24=$A23,$AB23,""))) -> 46174 | AC24: =IF($F24="","",IF($F24="订单头",$D24,IF($A24=$A23,$AC23,""))) -> 合肥荣事达太阳能有限公司 | AD24: =IF($F24="","",IF($F24="订单头",$E24,IF($A24=$A23,$AD23,""))) -> B型5P | AE24: =IF(OR($F24="组件",$F24="零件"),1,0) -> 1
A25: =IF($F25="","",COUNTIF($F$6:$F25,"订单头")) -> 2 | F25: 零件 | G25: =IF($F25="","",IF($F25="订单头","订单头",IF(AND($F25="零件",$J25<>""),IFERROR(SUMIFS($Y$6:$Y$205,$A$6:$A$205,$A25,$I$6:$I$205,$J25)&"."&$Z25,"父组件不存在"),$Y25))) -> 4.1 | H25: 定制件 | I25: =IF($F25="组件","C"&TEXT(COUNTIFS($A$6:$A25,$A25,$F$6:$F25,"组件"),"000"),"") | J25: =IF($F25="零件",IF($P25<>"","",IF(AND($A25=$A24,$F24="组件"),$I24,IF(AND($A25=$A24,$F24="零件",$J24<>""),$J24,""))),"") -> C002 | L25: B5机型物料号-10-00-A | M25: 底盘板 | O25: 2mm | Q25: 2 | R25: =IF(OR($F25="",$F25="订单头"),"",IF(AND($F25="零件",$J25<>""),IFERROR(SUMIFS($R$6:$R24,$A$6:$A24,$A25,$I$6:$I24,$J25)*IF($Q25="",1,$Q25),""),IF($P25="","",$P25*IF($Q25="",1,$Q25)))) -> 32 | S25: 件 | T25: 激光切割 | U25: 按父组件需求数量×2 | W25: 待确认 | X25: =IF($F25="","",IF($F25="订单头",0,IF($A25=$A24,$X24,0)+IF(OR($F25="组件",AND($F25="零件",$J25="")),1,0))) -> 4 | Y25: =IF($F25="","",IF($F25="订单头","",IF(AND($F25="零件",$J25<>""),"",$X25))) | Z25: =IF(AND($F25="零件",$J25<>""),COUNTIFS($A$6:$A25,$A25,$J$6:$J25,$J25,$F$6:$F25,"零件"),"") -> 1 | AA25: =IF($F25="","",IF($F25="订单头",$B25,IF($A25=$A24,$AA24,""))) -> RSD-20260601-002 | AB25: =IF($F25="","",IF($F25="订单头",$C25,IF($A25=$A24,$AB24,""))) -> 46174 | AC25: =IF($F25="","",IF($F25="订单头",$D25,IF($A25=$A24,$AC24,""))) -> 合肥荣事达太阳能有限公司 | AD25: =IF($F25="","",IF($F25="订单头",$E25,IF($A25=$A24,$AD24,""))) -> B型5P | AE25: =IF(OR($F25="组件",$F25="零件"),1,0) -> 1
A26: =IF($F26="","",COUNTIF($F$6:$F26,"订单头")) -> 2 | F26: 零件 | G26: =IF($F26="","",IF($F26="订单头","订单头",IF(AND($F26="零件",$J26<>""),IFERROR(SUMIFS($Y$6:$Y$205,$A$6:$A$205,$A26,$I$6:$I$205,$J26)&"."&$Z26,"父组件不存在"),$Y26))) -> 4.2 | H26: 定制件 | I26: =IF($F26="组件","C"&TEXT(COUNTIFS($A$6:$A26,$A26,$F$6:$F26,"组件"),"000"),"") | J26: =IF($F26="零件",IF($P26<>"","",IF(AND($A26=$A25,$F25="组件"),$I25,IF(AND($A26=$A25,$F25="零件",$J25<>""),$J25,""))),"") -> C002 | L26: B5机型物料号-10-00-B | M26: 底盘加强片 | O26: 1.5mm | Q26: 2 | R26: =IF(OR($F26="",$F26="订单头"),"",IF(AND($F26="零件",$J26<>""),IFERROR(SUMIFS($R$6:$R25,$A$6:$A25,$A26,$I$6:$I25,$J26)*IF($Q26="",1,$Q26),""),IF($P26="","",$P26*IF($Q26="",1,$Q26)))) -> 32 | S26: 件 | T26: 激光切割>折弯 | U26: 按父组件需求数量×2 | W26: 待确认 | X26: =IF($F26="","",IF($F26="订单头",0,IF($A26=$A25,$X25,0)+IF(OR($F26="组件",AND($F26="零件",$J26="")),1,0))) -> 4 | Y26: =IF($F26="","",IF($F26="订单头","",IF(AND($F26="零件",$J26<>""),"",$X26))) | Z26: =IF(AND($F26="零件",$J26<>""),COUNTIFS($A$6:$A26,$A26,$J$6:$J26,$J26,$F$6:$F26,"零件"),"") -> 2 | AA26: =IF($F26="","",IF($F26="订单头",$B26,IF($A26=$A25,$AA25,""))) -> RSD-20260601-002 | AB26: =IF($F26="","",IF($F26="订单头",$C26,IF($A26=$A25,$AB25,""))) -> 46174 | AC26: =IF($F26="","",IF($F26="订单头",$D26,IF($A26=$A25,$AC25,""))) -> 合肥荣事达太阳能有限公司 | AD26: =IF($F26="","",IF($F26="订单头",$E26,IF($A26=$A25,$AD25,""))) -> B型5P | AE26: =IF(OR($F26="组件",$F26="零件"),1,0) -> 1
A27: =IF($F27="","",COUNTIF($F$6:$F27,"订单头")) -> 2 | F27: 零件 | G27: =IF($F27="","",IF($F27="订单头","订单头",IF(AND($F27="零件",$J27<>""),IFERROR(SUMIFS($Y$6:$Y$205,$A$6:$A$205,$A27,$I$6:$I$205,$J27)&"."&$Z27,"父组件不存在"),$Y27))) -> 5 | H27: 外协件 | I27: =IF($F27="组件","C"&TEXT(COUNTIFS($A$6:$A27,$A27,$F$6:$F27,"组件"),"000"),"") | J27: =IF($F27="零件",IF($P27<>"","",IF(AND($A27=$A26,$F26="组件"),$I26,IF(AND($A27=$A26,$F26="零件",$J26<>""),$J26,""))),"") | K27: RS107023 | L27: B5机型物料号-10-04 | M27: 网罩 | P27: 32 | R27: =IF(OR($F27="",$F27="订单头"),"",IF(AND($F27="零件",$J27<>""),IFERROR(SUMIFS($R$6:$R26,$A$6:$A26,$A27,$I$6:$I26,$J27)*IF($Q27="",1,$Q27),""),IF($P27="","",$P27*IF($Q27="",1,$Q27)))) -> 32 | S27: 件 | U27: 钢丝网 | W27: 旧图 | X27: =IF($F27="","",IF($F27="订单头",0,IF($A27=$A26,$X26,0)+IF(OR($F27="组件",AND($F27="零件",$J27="")),1,0))) -> 5 | Y27: =IF($F27="","",IF($F27="订单头","",IF(AND($F27="零件",$J27<>""),"",$X27))) -> 5 | Z27: =IF(AND($F27="零件",$J27<>""),COUNTIFS($A$6:$A27,$A27,$J$6:$J27,$J27,$F$6:$F27,"零件"),"") | AA27: =IF($F27="","",IF($F27="订单头",$B27,IF($A27=$A26,$AA26,""))) -> RSD-20260601-002 | AB27: =IF($F27="","",IF($F27="订单头",$C27,IF($A27=$A26,$AB26,""))) -> 46174 | AC27: =IF($F27="","",IF($F27="订单头",$D27,IF($A27=$A26,$AC26,""))) -> 合肥荣事达太阳能有限公司 | AD27: =IF($F27="","",IF($F27="订单头",$E27,IF($A27=$A26,$AD26,""))) -> B型5P | AE27: =IF(OR($F27="组件",$F27="零件"),1,0) -> 1
A28: =IF($F28="","",COUNTIF($F$6:$F28,"订单头")) | G28: =IF($F28="","",IF($F28="订单头","订单头",IF(AND($F28="零件",$J28<>""),IFERROR(SUMIFS($Y$6:$Y$205,$A$6:$A$205,$A28,$I$6:$I$205,$J28)&"."&$Z28,"父组件不存在"),$Y28))) | I28: =IF($F28="组件","C"&TEXT(COUNTIFS($A$6:$A28,$A28,$F$6:$F28,"组件"),"000"),"") | J28: =IF($F28="零件",IF($P28<>"","",IF(AND($A28=$A27,$F27="组件"),$I27,IF(AND($A28=$A27,$F27="零件",$J27<>""),$J27,""))),"") | R28: =IF(OR($F28="",$F28="订单头"),"",IF(AND($F28="零件",$J28<>""),IFERROR(SUMIFS($R$6:$R27,$A$6:$A27,$A28,$I$6:$I27,$J28)*IF($Q28="",1,$Q28),""),IF($P28="","",$P28*IF($Q28="",1,$Q28)))) | X28: =IF($F28="","",IF($F28="订单头",0,IF($A28=$A27,$X27,0)+IF(OR($F28="组件",AND($F28="零件",$J28="")),1,0))) | Y28: =IF($F28="","",IF($F28="订单头","",IF(AND($F28="零件",$J28<>""),"",$X28))) | Z28: =IF(AND($F28="零件",$J28<>""),COUNTIFS($A$6:$A28,$A28,$J$6:$J28,$J28,$F$6:$F28,"零件"),"") | AA28: =IF($F28="","",IF($F28="订单头",$B28,IF($A28=$A27,$AA27,""))) | AB28: =IF($F28="","",IF($F28="订单头",$C28,IF($A28=$A27,$AB27,""))) | AC28: =IF($F28="","",IF($F28="订单头",$D28,IF($A28=$A27,$AC27,""))) | AD28: =IF($F28="","",IF($F28="订单头",$E28,IF($A28=$A27,$AD27,""))) | AE28: =IF(OR($F28="组件",$F28="零件"),1,0) -> 0
A29: =IF($F29="","",COUNTIF($F$6:$F29,"订单头")) -> 3 | B29: RSD-20260615-003 | C29: 46188 | D29: 合肥荣事达太阳能有限公司 | E29: D型8P | F29: 订单头 | G29: =IF($F29="","",IF($F29="订单头","订单头",IF(AND($F29="零件",$J29<>""),IFERROR(SUMIFS($Y$6:$Y$205,$A$6:$A$205,$A29,$I$6:$I$205,$J29)&"."&$Z29,"父组件不存在"),$Y29))) -> 订单头 | I29: =IF($F29="组件","C"&TEXT(COUNTIFS($A$6:$A29,$A29,$F$6:$F29,"组件"),"000"),"") | J29: =IF($F29="零件",IF($P29<>"","",IF(AND($A29=$A28,$F28="组件"),$I28,IF(AND($A29=$A28,$F28="零件",$J28<>""),$J28,""))),"") | R29: =IF(OR($F29="",$F29="订单头"),"",IF(AND($F29="零件",$J29<>""),IFERROR(SUMIFS($R$6:$R28,$A$6:$A28,$A29,$I$6:$I28,$J29)*IF($Q29="",1,$Q29),""),IF($P29="","",$P29*IF($Q29="",1,$Q29)))) | X29: =IF($F29="","",IF($F29="订单头",0,IF($A29=$A28,$X28,0)+IF(OR($F29="组件",AND($F29="零件",$J29="")),1,0))) -> 0 | Y29: =IF($F29="","",IF($F29="订单头","",IF(AND($F29="零件",$J29<>""),"",$X29))) | Z29: =IF(AND($F29="零件",$J29<>""),COUNTIFS($A$6:$A29,$A29,$J$6:$J29,$J29,$F$6:$F29,"零件"),"") | AA29: =IF($F29="","",IF($F29="订单头",$B29,IF($A29=$A28,$AA28,""))) -> RSD-20260615-003 | AB29: =IF($F29="","",IF($F29="订单头",$C29,IF($A29=$A28,$AB28,""))) -> 46188 | AC29: =IF($F29="","",IF($F29="订单头",$D29,IF($A29=$A28,$AC28,""))) -> 合肥荣事达太阳能有限公司 | AD29: =IF($F29="","",IF($F29="订单头",$E29,IF($A29=$A28,$AD28,""))) -> D型8P | AE29: =IF(OR($F29="组件",$F29="零件"),1,0) -> 0
A30: =IF($F30="","",COUNTIF($F$6:$F30,"订单头")) -> 3 | F30: 零件 | G30: =IF($F30="","",IF($F30="订单头","订单头",IF(AND($F30="零件",$J30<>""),IFERROR(SUMIFS($Y$6:$Y$205,$A$6:$A$205,$A30,$I$6:$I$205,$J30)&"."&$Z30,"父组件不存在"),$Y30))) -> 1 | H30: 通用件 | I30: =IF($F30="组件","C"&TEXT(COUNTIFS($A$6:$A30,$A30,$F$6:$F30,"组件"),"000"),"") | J30: =IF($F30="零件",IF($P30<>"","",IF(AND($A30=$A29,$F29="组件"),$I29,IF(AND($A30=$A29,$F29="零件",$J29<>""),$J29,""))),"") | K30: RS20703010033 | L30: D8-10-50-01 | M30: 顶盖 | O30: 1mm | P30: 8 | R30: =IF(OR($F30="",$F30="订单头"),"",IF(AND($F30="零件",$J30<>""),IFERROR(SUMIFS($R$6:$R29,$A$6:$A29,$A30,$I$6:$I29,$J30)*IF($Q30="",1,$Q30),""),IF($P30="","",$P30*IF($Q30="",1,$Q30)))) -> 8 | S30: 件 | U30: 样机款 | W30: 新图 | X30: =IF($F30="","",IF($F30="订单头",0,IF($A30=$A29,$X29,0)+IF(OR($F30="组件",AND($F30="零件",$J30="")),1,0))) -> 1 | Y30: =IF($F30="","",IF($F30="订单头","",IF(AND($F30="零件",$J30<>""),"",$X30))) -> 1 | Z30: =IF(AND($F30="零件",$J30<>""),COUNTIFS($A$6:$A30,$A30,$J$6:$J30,$J30,$F$6:$F30,"零件"),"") | AA30: =IF($F30="","",IF($F30="订单头",$B30,IF($A30=$A29,$AA29,""))) -> RSD-20260615-003 | AB30: =IF($F30="","",IF($F30="订单头",$C30,IF($A30=$A29,$AB29,""))) -> 46188 | AC30: =IF($F30="","",IF($F30="订单头",$D30,IF($A30=$A29,$AC29,""))) -> 合肥荣事达太阳能有限公司 | AD30: =IF($F30="","",IF($F30="订单头",$E30,IF($A30=$A29,$AD29,""))) -> D型8P | AE30: =IF(OR($F30="组件",$F30="零件"),1,0) -> 1
A31: =IF($F31="","",COUNTIF($F$6:$F31,"订单头")) -> 3 | F31: 组件 | G31: =IF($F31="","",IF($F31="订单头","订单头",IF(AND($F31="零件",$J31<>""),IFERROR(SUMIFS($Y$6:$Y$205,$A$6:$A$205,$A31,$I$6:$I$205,$J31)&"."&$Z31,"父组件不存在"),$Y31))) -> 2 | H31: 通用件 | I31: =IF($F31="组件","C"&TEXT(COUNTIFS($A$6:$A31,$A31,$F$6:$F31,"组件"),"000"),"") -> C001 | J31: =IF($F31="零件",IF($P31<>"","",IF(AND($A31=$A30,$F30="组件"),$I30,IF(AND($A31=$A30,$F30="零件",$J30<>""),$J30,""))),"") | K31: RS20701020216 | L31: D8-10-30 | M31: 电控支架组件 | O31: 2mm | P31: 8 | Q31: 1 | R31: =IF(OR($F31="",$F31="订单头"),"",IF(AND($F31="零件",$J31<>""),IFERROR(SUMIFS($R$6:$R30,$A$6:$A30,$A31,$I$6:$I30,$J31)*IF($Q31="",1,$Q31),""),IF($P31="","",$P31*IF($Q31="",1,$Q31)))) -> 8 | S31: 套 | T31: 装配 | U31: 螺丝组装 | V31: 46188 | W31: 新图 | X31: =IF($F31="","",IF($F31="订单头",0,IF($A31=$A30,$X30,0)+IF(OR($F31="组件",AND($F31="零件",$J31="")),1,0))) -> 2 | Y31: =IF($F31="","",IF($F31="订单头","",IF(AND($F31="零件",$J31<>""),"",$X31))) -> 2 | Z31: =IF(AND($F31="零件",$J31<>""),COUNTIFS($A$6:$A31,$A31,$J$6:$J31,$J31,$F$6:$F31,"零件"),"") | AA31: =IF($F31="","",IF($F31="订单头",$B31,IF($A31=$A30,$AA30,""))) -> RSD-20260615-003 | AB31: =IF($F31="","",IF($F31="订单头",$C31,IF($A31=$A30,$AB30,""))) -> 46188 | AC31: =IF($F31="","",IF($F31="订单头",$D31,IF($A31=$A30,$AC30,""))) -> 合肥荣事达太阳能有限公司 | AD31: =IF($F31="","",IF($F31="订单头",$E31,IF($A31=$A30,$AD30,""))) -> D型8P | AE31: =IF(OR($F31="组件",$F31="零件"),1,0) -> 1
A32: =IF($F32="","",COUNTIF($F$6:$F32,"订单头")) -> 3 | F32: 零件 | G32: =IF($F32="","",IF($F32="订单头","订单头",IF(AND($F32="零件",$J32<>""),IFERROR(SUMIFS($Y$6:$Y$205,$A$6:$A$205,$A32,$I$6:$I$205,$J32)&"."&$Z32,"父组件不存在"),$Y32))) -> 2.1 | H32: 通用件 | I32: =IF($F32="组件","C"&TEXT(COUNTIFS($A$6:$A32,$A32,$F$6:$F32,"组件"),"000"),"") | J32: =IF($F32="零件",IF($P32<>"","",IF(AND($A32=$A31,$F31="组件"),$I31,IF(AND($A32=$A31,$F31="零件",$J31<>""),$J31,""))),"") -> C001 | L32: D8-10-30-A | M32: 支架主板 | O32: 2mm | Q32: 1 | R32: =IF(OR($F32="",$F32="订单头"),"",IF(AND($F32="零件",$J32<>""),IFERROR(SUMIFS($R$6:$R31,$A$6:$A31,$A32,$I$6:$I31,$J32)*IF($Q32="",1,$Q32),""),IF($P32="","",$P32*IF($Q32="",1,$Q32)))) -> 8 | S32: 件 | T32: 激光切割>折弯 | U32: 组件 C001 的子件 | V32: 46188 | W32: 新图 | X32: =IF($F32="","",IF($F32="订单头",0,IF($A32=$A31,$X31,0)+IF(OR($F32="组件",AND($F32="零件",$J32="")),1,0))) -> 2 | Y32: =IF($F32="","",IF($F32="订单头","",IF(AND($F32="零件",$J32<>""),"",$X32))) | Z32: =IF(AND($F32="零件",$J32<>""),COUNTIFS($A$6:$A32,$A32,$J$6:$J32,$J32,$F$6:$F32,"零件"),"") -> 1 | AA32: =IF($F32="","",IF($F32="订单头",$B32,IF($A32=$A31,$AA31,""))) -> RSD-20260615-003 | AB32: =IF($F32="","",IF($F32="订单头",$C32,IF($A32=$A31,$AB31,""))) -> 46188 | AC32: =IF($F32="","",IF($F32="订单头",$D32,IF($A32=$A31,$AC31,""))) -> 合肥荣事达太阳能有限公司 | AD32: =IF($F32="","",IF($F32="订单头",$E32,IF($A32=$A31,$AD31,""))) -> D型8P | AE32: =IF(OR($F32="组件",$F32="零件"),1,0) -> 1
A33: =IF($F33="","",COUNTIF($F$6:$F33,"订单头")) -> 3 | F33: 零件 | G33: =IF($F33="","",IF($F33="订单头","订单头",IF(AND($F33="零件",$J33<>""),IFERROR(SUMIFS($Y$6:$Y$205,$A$6:$A$205,$A33,$I$6:$I$205,$J33)&"."&$Z33,"父组件不存在"),$Y33))) -> 2.2 | H33: 通用件 | I33: =IF($F33="组件","C"&TEXT(COUNTIFS($A$6:$A33,$A33,$F$6:$F33,"组件"),"000"),"") | J33: =IF($F33="零件",IF($P33<>"","",IF(AND($A33=$A32,$F32="组件"),$I32,IF(AND($A33=$A32,$F32="零件",$J32<>""),$J32,""))),"") -> C001 | L33: D8-10-30-B | M33: 支架加强片 | O33: 1.5mm | Q33: 2 | R33: =IF(OR($F33="",$F33="订单头"),"",IF(AND($F33="零件",$J33<>""),IFERROR(SUMIFS($R$6:$R32,$A$6:$A32,$A33,$I$6:$I32,$J33)*IF($Q33="",1,$Q33),""),IF($P33="","",$P33*IF($Q33="",1,$Q33)))) -> 16 | S33: 件 | T33: 激光切割 | U33: 每套组件 2 件 | V33: 46188 | W33: 新图 | X33: =IF($F33="","",IF($F33="订单头",0,IF($A33=$A32,$X32,0)+IF(OR($F33="组件",AND($F33="零件",$J33="")),1,0))) -> 2 | Y33: =IF($F33="","",IF($F33="订单头","",IF(AND($F33="零件",$J33<>""),"",$X33))) | Z33: =IF(AND($F33="零件",$J33<>""),COUNTIFS($A$6:$A33,$A33,$J$6:$J33,$J33,$F$6:$F33,"零件"),"") -> 2 | AA33: =IF($F33="","",IF($F33="订单头",$B33,IF($A33=$A32,$AA32,""))) -> RSD-20260615-003 | AB33: =IF($F33="","",IF($F33="订单头",$C33,IF($A33=$A32,$AB32,""))) -> 46188 | AC33: =IF($F33="","",IF($F33="订单头",$D33,IF($A33=$A32,$AC32,""))) -> 合肥荣事达太阳能有限公司 | AD33: =IF($F33="","",IF($F33="订单头",$E33,IF($A33=$A32,$AD32,""))) -> D型8P | AE33: =IF(OR($F33="组件",$F33="零件"),1,0) -> 1
A34: =IF($F34="","",COUNTIF($F$6:$F34,"订单头")) -> 3 | F34: 零件 | G34: =IF($F34="","",IF($F34="订单头","订单头",IF(AND($F34="零件",$J34<>""),IFERROR(SUMIFS($Y$6:$Y$205,$A$6:$A$205,$A34,$I$6:$I$205,$J34)&"."&$Z34,"父组件不存在"),$Y34))) -> 3 | H34: 外协件 | I34: =IF($F34="组件","C"&TEXT(COUNTIFS($A$6:$A34,$A34,$F$6:$F34,"组件"),"000"),"") | J34: =IF($F34="零件",IF($P34<>"","",IF(AND($A34=$A33,$F33="组件"),$I33,IF(AND($A34=$A33,$F33="零件",$J33<>""),$J33,""))),"") | K34: RS20707010049 | L34: D8-10-04 | M34: 网罩 | P34: 8 | R34: =IF(OR($F34="",$F34="订单头"),"",IF(AND($F34="零件",$J34<>""),IFERROR(SUMIFS($R$6:$R33,$A$6:$A33,$A34,$I$6:$I33,$J34)*IF($Q34="",1,$Q34),""),IF($P34="","",$P34*IF($Q34="",1,$Q34)))) -> 8 | S34: 件 | U34: 黑色 | W34: 待确认 | X34: =IF($F34="","",IF($F34="订单头",0,IF($A34=$A33,$X33,0)+IF(OR($F34="组件",AND($F34="零件",$J34="")),1,0))) -> 3 | Y34: =IF($F34="","",IF($F34="订单头","",IF(AND($F34="零件",$J34<>""),"",$X34))) -> 3 | Z34: =IF(AND($F34="零件",$J34<>""),COUNTIFS($A$6:$A34,$A34,$J$6:$J34,$J34,$F$6:$F34,"零件"),"") | AA34: =IF($F34="","",IF($F34="订单头",$B34,IF($A34=$A33,$AA33,""))) -> RSD-20260615-003 | AB34: =IF($F34="","",IF($F34="订单头",$C34,IF($A34=$A33,$AB33,""))) -> 46188 | AC34: =IF($F34="","",IF($F34="订单头",$D34,IF($A34=$A33,$AC33,""))) -> 合肥荣事达太阳能有限公司 | AD34: =IF($F34="","",IF($F34="订单头",$E34,IF($A34=$A33,$AD33,""))) -> D型8P | AE34: =IF(OR($F34="组件",$F34="零件"),1,0) -> 1
A35: =IF($F35="","",COUNTIF($F$6:$F35,"订单头")) | G35: =IF($F35="","",IF($F35="订单头","订单头",IF(AND($F35="零件",$J35<>""),IFERROR(SUMIFS($Y$6:$Y$205,$A$6:$A$205,$A35,$I$6:$I$205,$J35)&"."&$Z35,"父组件不存在"),$Y35))) | I35: =IF($F35="组件","C"&TEXT(COUNTIFS($A$6:$A35,$A35,$F$6:$F35,"组件"),"000"),"") | J35: =IF($F35="零件",IF($P35<>"","",IF(AND($A35=$A34,$F34="组件"),$I34,IF(AND($A35=$A34,$F34="零件",$J34<>""),$J34,""))),"") | R35: =IF(OR($F35="",$F35="订单头"),"",IF(AND($F35="零件",$J35<>""),IFERROR(SUMIFS($R$6:$R34,$A$6:$A34,$A35,$I$6:$I34,$J35)*IF($Q35="",1,$Q35),""),IF($P35="","",$P35*IF($Q35="",1,$Q35)))) | X35: =IF($F35="","",IF($F35="订单头",0,IF($A35=$A34,$X34,0)+IF(OR($F35="组件",AND($F35="零件",$J35="")),1,0))) | Y35: =IF($F35="","",IF($F35="订单头","",IF(AND($F35="零件",$J35<>""),"",$X35))) | Z35: =IF(AND($F35="零件",$J35<>""),COUNTIFS($A$6:$A35,$A35,$J$6:$J35,$J35,$F$6:$F35,"零件"),"") | AA35: =IF($F35="","",IF($F35="订单头",$B35,IF($A35=$A34,$AA34,""))) | AB35: =IF($F35="","",IF($F35="订单头",$C35,IF($A35=$A34,$AB34,""))) | AC35: =IF($F35="","",IF($F35="订单头",$D35,IF($A35=$A34,$AC34,""))) | AD35: =IF($F35="","",IF($F35="订单头",$E35,IF($A35=$A34,$AD34,""))) | AE35: =IF(OR($F35="组件",$F35="零件"),1,0) -> 0
A36: =IF($F36="","",COUNTIF($F$6:$F36,"订单头")) | G36: =IF($F36="","",IF($F36="订单头","订单头",IF(AND($F36="零件",$J36<>""),IFERROR(SUMIFS($Y$6:$Y$205,$A$6:$A$205,$A36,$I$6:$I$205,$J36)&"."&$Z36,"父组件不存在"),$Y36))) | I36: =IF($F36="组件","C"&TEXT(COUNTIFS($A$6:$A36,$A36,$F$6:$F36,"组件"),"000"),"") | J36: =IF($F36="零件",IF($P36<>"","",IF(AND($A36=$A35,$F35="组件"),$I35,IF(AND($A36=$A35,$F35="零件",$J35<>""),$J35,""))),"") | R36: =IF(OR($F36="",$F36="订单头"),"",IF(AND($F36="零件",$J36<>""),IFERROR(SUMIFS($R$6:$R35,$A$6:$A35,$A36,$I$6:$I35,$J36)*IF($Q36="",1,$Q36),""),IF($P36="","",$P36*IF($Q36="",1,$Q36)))) | X36: =IF($F36="","",IF($F36="订单头",0,IF($A36=$A35,$X35,0)+IF(OR($F36="组件",AND($F36="零件",$J36="")),1,0))) | Y36: =IF($F36="","",IF($F36="订单头","",IF(AND($F36="零件",$J36<>""),"",$X36))) | Z36: =IF(AND($F36="零件",$J36<>""),COUNTIFS($A$6:$A36,$A36,$J$6:$J36,$J36,$F$6:$F36,"零件"),"") | AA36: =IF($F36="","",IF($F36="订单头",$B36,IF($A36=$A35,$AA35,""))) | AB36: =IF($F36="","",IF($F36="订单头",$C36,IF($A36=$A35,$AB35,""))) | AC36: =IF($F36="","",IF($F36="订单头",$D36,IF($A36=$A35,$AC35,""))) | AD36: =IF($F36="","",IF($F36="订单头",$E36,IF($A36=$A35,$AD35,""))) | AE36: =IF(OR($F36="组件",$F36="零件"),1,0) -> 0
A37: =IF($F37="","",COUNTIF($F$6:$F37,"订单头")) | G37: =IF($F37="","",IF($F37="订单头","订单头",IF(AND($F37="零件",$J37<>""),IFERROR(SUMIFS($Y$6:$Y$205,$A$6:$A$205,$A37,$I$6:$I$205,$J37)&"."&$Z37,"父组件不存在"),$Y37))) | I37: =IF($F37="组件","C"&TEXT(COUNTIFS($A$6:$A37,$A37,$F$6:$F37,"组件"),"000"),"") | J37: =IF($F37="零件",IF($P37<>"","",IF(AND($A37=$A36,$F36="组件"),$I36,IF(AND($A37=$A36,$F36="零件",$J36<>""),$J36,""))),"") | R37: =IF(OR($F37="",$F37="订单头"),"",IF(AND($F37="零件",$J37<>""),IFERROR(SUMIFS($R$6:$R36,$A$6:$A36,$A37,$I$6:$I36,$J37)*IF($Q37="",1,$Q37),""),IF($P37="","",$P37*IF($Q37="",1,$Q37)))) | X37: =IF($F37="","",IF($F37="订单头",0,IF($A37=$A36,$X36,0)+IF(OR($F37="组件",AND($F37="零件",$J37="")),1,0))) | Y37: =IF($F37="","",IF($F37="订单头","",IF(AND($F37="零件",$J37<>""),"",$X37))) | Z37: =IF(AND($F37="零件",$J37<>""),COUNTIFS($A$6:$A37,$A37,$J$6:$J37,$J37,$F$6:$F37,"零件"),"") | AA37: =IF($F37="","",IF($F37="订单头",$B37,IF($A37=$A36,$AA36,""))) | AB37: =IF($F37="","",IF($F37="订单头",$C37,IF($A37=$A36,$AB36,""))) | AC37: =IF($F37="","",IF($F37="订单头",$D37,IF($A37=$A36,$AC36,""))) | AD37: =IF($F37="","",IF($F37="订单头",$E37,IF($A37=$A36,$AD36,""))) | AE37: =IF(OR($F37="组件",$F37="零件"),1,0) -> 0
A38: =IF($F38="","",COUNTIF($F$6:$F38,"订单头")) | G38: =IF($F38="","",IF($F38="订单头","订单头",IF(AND($F38="零件",$J38<>""),IFERROR(SUMIFS($Y$6:$Y$205,$A$6:$A$205,$A38,$I$6:$I$205,$J38)&"."&$Z38,"父组件不存在"),$Y38))) | I38: =IF($F38="组件","C"&TEXT(COUNTIFS($A$6:$A38,$A38,$F$6:$F38,"组件"),"000"),"") | J38: =IF($F38="零件",IF($P38<>"","",IF(AND($A38=$A37,$F37="组件"),$I37,IF(AND($A38=$A37,$F37="零件",$J37<>""),$J37,""))),"") | R38: =IF(OR($F38="",$F38="订单头"),"",IF(AND($F38="零件",$J38<>""),IFERROR(SUMIFS($R$6:$R37,$A$6:$A37,$A38,$I$6:$I37,$J38)*IF($Q38="",1,$Q38),""),IF($P38="","",$P38*IF($Q38="",1,$Q38)))) | X38: =IF($F38="","",IF($F38="订单头",0,IF($A38=$A37,$X37,0)+IF(OR($F38="组件",AND($F38="零件",$J38="")),1,0))) | Y38: =IF($F38="","",IF($F38="订单头","",IF(AND($F38="零件",$J38<>""),"",$X38))) | Z38: =IF(AND($F38="零件",$J38<>""),COUNTIFS($A$6:$A38,$A38,$J$6:$J38,$J38,$F$6:$F38,"零件"),"") | AA38: =IF($F38="","",IF($F38="订单头",$B38,IF($A38=$A37,$AA37,""))) | AB38: =IF($F38="","",IF($F38="订单头",$C38,IF($A38=$A37,$AB37,""))) | AC38: =IF($F38="","",IF($F38="订单头",$D38,IF($A38=$A37,$AC37,""))) | AD38: =IF($F38="","",IF($F38="订单头",$E38,IF($A38=$A37,$AD37,""))) | AE38: =IF(OR($F38="组件",$F38="零件"),1,0) -> 0
A39: =IF($F39="","",COUNTIF($F$6:$F39,"订单头")) | G39: =IF($F39="","",IF($F39="订单头","订单头",IF(AND($F39="零件",$J39<>""),IFERROR(SUMIFS($Y$6:$Y$205,$A$6:$A$205,$A39,$I$6:$I$205,$J39)&"."&$Z39,"父组件不存在"),$Y39))) | I39: =IF($F39="组件","C"&TEXT(COUNTIFS($A$6:$A39,$A39,$F$6:$F39,"组件"),"000"),"") | J39: =IF($F39="零件",IF($P39<>"","",IF(AND($A39=$A38,$F38="组件"),$I38,IF(AND($A39=$A38,$F38="零件",$J38<>""),$J38,""))),"") | R39: =IF(OR($F39="",$F39="订单头"),"",IF(AND($F39="零件",$J39<>""),IFERROR(SUMIFS($R$6:$R38,$A$6:$A38,$A39,$I$6:$I38,$J39)*IF($Q39="",1,$Q39),""),IF($P39="","",$P39*IF($Q39="",1,$Q39)))) | X39: =IF($F39="","",IF($F39="订单头",0,IF($A39=$A38,$X38,0)+IF(OR($F39="组件",AND($F39="零件",$J39="")),1,0))) | Y39: =IF($F39="","",IF($F39="订单头","",IF(AND($F39="零件",$J39<>""),"",$X39))) | Z39: =IF(AND($F39="零件",$J39<>""),COUNTIFS($A$6:$A39,$A39,$J$6:$J39,$J39,$F$6:$F39,"零件"),"") | AA39: =IF($F39="","",IF($F39="订单头",$B39,IF($A39=$A38,$AA38,""))) | AB39: =IF($F39="","",IF($F39="订单头",$C39,IF($A39=$A38,$AB38,""))) | AC39: =IF($F39="","",IF($F39="订单头",$D39,IF($A39=$A38,$AC38,""))) | AD39: =IF($F39="","",IF($F39="订单头",$E39,IF($A39=$A38,$AD38,""))) | AE39: =IF(OR($F39="组件",$F39="零件"),1,0) -> 0
A40: =IF($F40="","",COUNTIF($F$6:$F40,"订单头")) | G40: =IF($F40="","",IF($F40="订单头","订单头",IF(AND($F40="零件",$J40<>""),IFERROR(SUMIFS($Y$6:$Y$205,$A$6:$A$205,$A40,$I$6:$I$205,$J40)&"."&$Z40,"父组件不存在"),$Y40))) | I40: =IF($F40="组件","C"&TEXT(COUNTIFS($A$6:$A40,$A40,$F$6:$F40,"组件"),"000"),"") | J40: =IF($F40="零件",IF($P40<>"","",IF(AND($A40=$A39,$F39="组件"),$I39,IF(AND($A40=$A39,$F39="零件",$J39<>""),$J39,""))),"") | R40: =IF(OR($F40="",$F40="订单头"),"",IF(AND($F40="零件",$J40<>""),IFERROR(SUMIFS($R$6:$R39,$A$6:$A39,$A40,$I$6:$I39,$J40)*IF($Q40="",1,$Q40),""),IF($P40="","",$P40*IF($Q40="",1,$Q40)))) | X40: =IF($F40="","",IF($F40="订单头",0,IF($A40=$A39,$X39,0)+IF(OR($F40="组件",AND($F40="零件",$J40="")),1,0))) | Y40: =IF($F40="","",IF($F40="订单头","",IF(AND($F40="零件",$J40<>""),"",$X40))) | Z40: =IF(AND($F40="零件",$J40<>""),COUNTIFS($A$6:$A40,$A40,$J$6:$J40,$J40,$F$6:$F40,"零件"),"") | AA40: =IF($F40="","",IF($F40="订单头",$B40,IF($A40=$A39,$AA39,""))) | AB40: =IF($F40="","",IF($F40="订单头",$C40,IF($A40=$A39,$AB39,""))) | AC40: =IF($F40="","",IF($F40="订单头",$D40,IF($A40=$A39,$AC39,""))) | AD40: =IF($F40="","",IF($F40="订单头",$E40,IF($A40=$A39,$AD39,""))) | AE40: =IF(OR($F40="组件",$F40="零件"),1,0) -> 0
A41: =IF($F41="","",COUNTIF($F$6:$F41,"订单头")) | G41: =IF($F41="","",IF($F41="订单头","订单头",IF(AND($F41="零件",$J41<>""),IFERROR(SUMIFS($Y$6:$Y$205,$A$6:$A$205,$A41,$I$6:$I$205,$J41)&"."&$Z41,"父组件不存在"),$Y41))) | I41: =IF($F41="组件","C"&TEXT(COUNTIFS($A$6:$A41,$A41,$F$6:$F41,"组件"),"000"),"") | J41: =IF($F41="零件",IF($P41<>"","",IF(AND($A41=$A40,$F40="组件"),$I40,IF(AND($A41=$A40,$F40="零件",$J40<>""),$J40,""))),"") | R41: =IF(OR($F41="",$F41="订单头"),"",IF(AND($F41="零件",$J41<>""),IFERROR(SUMIFS($R$6:$R40,$A$6:$A40,$A41,$I$6:$I40,$J41)*IF($Q41="",1,$Q41),""),IF($P41="","",$P41*IF($Q41="",1,$Q41)))) | X41: =IF($F41="","",IF($F41="订单头",0,IF($A41=$A40,$X40,0)+IF(OR($F41="组件",AND($F41="零件",$J41="")),1,0))) | Y41: =IF($F41="","",IF($F41="订单头","",IF(AND($F41="零件",$J41<>""),"",$X41))) | Z41: =IF(AND($F41="零件",$J41<>""),COUNTIFS($A$6:$A41,$A41,$J$6:$J41,$J41,$F$6:$F41,"零件"),"") | AA41: =IF($F41="","",IF($F41="订单头",$B41,IF($A41=$A40,$AA40,""))) | AB41: =IF($F41="","",IF($F41="订单头",$C41,IF($A41=$A40,$AB40,""))) | AC41: =IF($F41="","",IF($F41="订单头",$D41,IF($A41=$A40,$AC40,""))) | AD41: =IF($F41="","",IF($F41="订单头",$E41,IF($A41=$A40,$AD40,""))) | AE41: =IF(OR($F41="组件",$F41="零件"),1,0) -> 0
...

Sheet ERP导入清单
A1: ERP导入清单（自动生成，不手填）
A2: 上传 ERP 时读取本表；筛选“行类型”不为空的行。字段顺序已与清单台账保持一致，订单头行不会导入。
A4: 订单块(自动) | B4: 订单编号 | C4: 制单日期 | D4: 客户名称 | E4: 项目型号 | F4: 行类型 | G4: 自动序号 | H4: 零件类型 | I4: 组件编号(自动) | J4: 所属组件编号(自动/可改) | K4: 物料号 | L4: 图号 | M4: 产品名称 | N4: 展开尺寸 | O4: 厚度 | P4: 订单数 | Q4: 单套用量 | R4: 需求数量(自动) | S4: 单位 | T4: 工艺路线 | U4: 工艺备注 | V4: 图纸日期 | W4: 图纸状态 | X4: helperUploadSeq
A5: =IFERROR(IF(清单台账!$AE6=1,清单台账!$A6,""),"") | B5: =IFERROR(IF(清单台账!$AE6=1,清单台账!$AA6,""),"") | C5: =IFERROR(IF(清单台账!$AE6=1,清单台账!$AB6,""),"") | D5: =IFERROR(IF(清单台账!$AE6=1,清单台账!$AC6,""),"") | E5: =IFERROR(IF(清单台账!$AE6=1,清单台账!$AD6,""),"") | F5: =IFERROR(IF(清单台账!$AE6=1,清单台账!$F6,""),"") | G5: =IFERROR(IF(清单台账!$AE6=1,清单台账!$G6,""),"") | H5: =IFERROR(IF(清单台账!$AE6=1,清单台账!$H6,""),"") | I5: =IFERROR(IF(清单台账!$AE6=1,清单台账!$I6,""),"") | J5: =IFERROR(IF(清单台账!$AE6=1,清单台账!$J6,""),"") | K5: =IFERROR(IF(清单台账!$AE6=1,清单台账!$K6,""),"") | L5: =IFERROR(IF(清单台账!$AE6=1,清单台账!$L6,""),"") | M5: =IFERROR(IF(清单台账!$AE6=1,清单台账!$M6,""),"") | N5: =IFERROR(IF(清单台账!$AE6=1,清单台账!$N6,""),"") | O5: =IFERROR(IF(清单台账!$AE6=1,清单台账!$O6,""),"") | P5: =IFERROR(IF(清单台账!$AE6=1,清单台账!$P6,""),"") | Q5: =IFERROR(IF(清单台账!$AE6=1,清单台账!$Q6,""),"") | R5: =IFERROR(IF(清单台账!$AE6=1,清单台账!$R6,""),"") | S5: =IFERROR(IF(清单台账!$AE6=1,清单台账!$S6,""),"") | T5: =IFERROR(IF(清单台账!$AE6=1,清单台账!$T6,""),"") | U5: =IFERROR(IF(清单台账!$AE6=1,清单台账!$U6,""),"") | V5: =IFERROR(IF(清单台账!$AE6=1,清单台账!$V6,""),"") | W5: =IFERROR(IF(清单台账!$AE6=1,清单台账!$W6,""),"") | X5: =IF($F5<>"",0+1,"")
A6: =IFERROR(IF(清单台账!$AE7=1,清单台账!$A7,""),"") -> 1 | B6: =IFERROR(IF(清单台账!$AE7=1,清单台账!$AA7,""),"") -> RSD-20260510-001 | C6: =IFERROR(IF(清单台账!$AE7=1,清单台账!$AB7,""),"") -> 46126 | D6: =IFERROR(IF(清单台账!$AE7=1,清单台账!$AC7,""),"") -> 合肥荣事达太阳能有限公司 | E6: =IFERROR(IF(清单台账!$AE7=1,清单台账!$AD7,""),"") -> C型15P | F6: =IFERROR(IF(清单台账!$AE7=1,清单台账!$F7,""),"") -> 零件 | G6: =IFERROR(IF(清单台账!$AE7=1,清单台账!$G7,""),"") -> 1 | H6: =IFERROR(IF(清单台账!$AE7=1,清单台账!$H7,""),"") -> 通用件 | I6: =IFERROR(IF(清单台账!$AE7=1,清单台账!$I7,""),"") | J6: =IFERROR(IF(清单台账!$AE7=1,清单台账!$J7,""),"") | K6: =IFERROR(IF(清单台账!$AE7=1,清单台账!$K7,""),"") -> RS10703010033 | L6: =IFERROR(IF(清单台账!$AE7=1,清单台账!$L7,""),"") -> RBKS-300DBII-10-50-01 | M6: =IFERROR(IF(清单台账!$AE7=1,清单台账!$M7,""),"") -> 顶盖 | N6: =IFERROR(IF(清单台账!$AE7=1,清单台账!$N7,""),"") -> 0 | O6: =IFERROR(IF(清单台账!$AE7=1,清单台账!$O7,""),"") -> 1mm | P6: =IFERROR(IF(清单台账!$AE7=1,清单台账!$P7,""),"") -> 16 | Q6: =IFERROR(IF(清单台账!$AE7=1,清单台账!$Q7,""),"") -> 0 | R6: =IFERROR(IF(清单台账!$AE7=1,清单台账!$R7,""),"") -> 16 | S6: =IFERROR(IF(清单台账!$AE7=1,清单台账!$S7,""),"") -> 件 | T6: =IFERROR(IF(清单台账!$AE7=1,清单台账!$T7,""),"") -> 0 | U6: =IFERROR(IF(清单台账!$AE7=1,清单台账!$U7,""),"") -> 百胜样机款 | V6: =IFERROR(IF(清单台账!$AE7=1,清单台账!$V7,""),"") -> 0 | W6: =IFERROR(IF(清单台账!$AE7=1,清单台账!$W7,""),"") -> 旧图 | X6: =IF($F6<>"",IFERROR(MAX($X$5:$X5),0)+1,"") -> 1
A7: =IFERROR(IF(清单台账!$AE8=1,清单台账!$A8,""),"") -> 1 | B7: =IFERROR(IF(清单台账!$AE8=1,清单台账!$AA8,""),"") -> RSD-20260510-001 | C7: =IFERROR(IF(清单台账!$AE8=1,清单台账!$AB8,""),"") -> 46126 | D7: =IFERROR(IF(清单台账!$AE8=1,清单台账!$AC8,""),"") -> 合肥荣事达太阳能有限公司 | E7: =IFERROR(IF(清单台账!$AE8=1,清单台账!$AD8,""),"") -> C型15P | F7: =IFERROR(IF(清单台账!$AE8=1,清单台账!$F8,""),"") -> 零件 | G7: =IFERROR(IF(清单台账!$AE8=1,清单台账!$G8,""),"") -> 2 | H7: =IFERROR(IF(清单台账!$AE8=1,清单台账!$H8,""),"") -> 通用件 | I7: =IFERROR(IF(清单台账!$AE8=1,清单台账!$I8,""),"") | J7: =IFERROR(IF(清单台账!$AE8=1,清单台账!$J8,""),"") | K7: =IFERROR(IF(清单台账!$AE8=1,清单台账!$K8,""),"") -> RS10701050458 | L7: =IFERROR(IF(清单台账!$AE8=1,清单台账!$L8,""),"") -> RBKS-300DBII-10-01 | M7: =IFERROR(IF(清单台账!$AE8=1,清单台账!$M8,""),"") -> 左侧封板 | N7: =IFERROR(IF(清单台账!$AE8=1,清单台账!$N8,""),"") -> 0 | O7: =IFERROR(IF(清单台账!$AE8=1,清单台账!$O8,""),"") -> 1mm | P7: =IFERROR(IF(清单台账!$AE8=1,清单台账!$P8,""),"") -> 16 | Q7: =IFERROR(IF(清单台账!$AE8=1,清单台账!$Q8,""),"") -> 0 | R7: =IFERROR(IF(清单台账!$AE8=1,清单台账!$R8,""),"") -> 16 | S7: =IFERROR(IF(清单台账!$AE8=1,清单台账!$S8,""),"") -> 件 | T7: =IFERROR(IF(清单台账!$AE8=1,清单台账!$T8,""),"") -> 激光切割>折弯 | U7: =IFERROR(IF(清单台账!$AE8=1,清单台账!$U8,""),"") -> 百胜样机款 | V7: =IFERROR(IF(清单台账!$AE8=1,清单台账!$V8,""),"") -> 0 | W7: =IFERROR(IF(清单台账!$AE8=1,清单台账!$W8,""),"") -> 旧图 | X7: =IF($F7<>"",IFERROR(MAX($X$5:$X6),0)+1,"") -> 2
A8: =IFERROR(IF(清单台账!$AE9=1,清单台账!$A9,""),"") -> 1 | B8: =IFERROR(IF(清单台账!$AE9=1,清单台账!$AA9,""),"") -> RSD-20260510-001 | C8: =IFERROR(IF(清单台账!$AE9=1,清单台账!$AB9,""),"") -> 46126 | D8: =IFERROR(IF(清单台账!$AE9=1,清单台账!$AC9,""),"") -> 合肥荣事达太阳能有限公司 | E8: =IFERROR(IF(清单台账!$AE9=1,清单台账!$AD9,""),"") -> C型15P | F8: =IFERROR(IF(清单台账!$AE9=1,清单台账!$F9,""),"") -> 零件 | G8: =IFERROR(IF(清单台账!$AE9=1,清单台账!$G9,""),"") -> 3 | H8: =IFERROR(IF(清单台账!$AE9=1,清单台账!$H9,""),"") -> 通用件 | I8: =IFERROR(IF(清单台账!$AE9=1,清单台账!$I9,""),"") | J8: =IFERROR(IF(清单台账!$AE9=1,清单台账!$J9,""),"") | K8: =IFERROR(IF(清单台账!$AE9=1,清单台账!$K9,""),"") -> RS10701050459 | L8: =IFERROR(IF(清单台账!$AE9=1,清单台账!$L9,""),"") -> RBKS-300DBII-10-03 | M8: =IFERROR(IF(清单台账!$AE9=1,清单台账!$M9,""),"") -> 前风机板（钢丝网） | N8: =IFERROR(IF(清单台账!$AE9=1,清单台账!$N9,""),"") -> 0 | O8: =IFERROR(IF(清单台账!$AE9=1,清单台账!$O9,""),"") -> 1mm | P8: =IFERROR(IF(清单台账!$AE9=1,清单台账!$P9,""),"") -> 16 | Q8: =IFERROR(IF(清单台账!$AE9=1,清单台账!$Q9,""),"") -> 0 | R8: =IFERROR(IF(清单台账!$AE9=1,清单台账!$R9,""),"") -> 16 | S8: =IFERROR(IF(清单台账!$AE9=1,清单台账!$S9,""),"") -> 件 | T8: =IFERROR(IF(清单台账!$AE9=1,清单台账!$T9,""),"") -> 激光切割>折弯 | U8: =IFERROR(IF(清单台账!$AE9=1,清单台账!$U9,""),"") -> 增冷凝器孔 | V8: =IFERROR(IF(清单台账!$AE9=1,清单台账!$V9,""),"") -> 44657 | W8: =IFERROR(IF(清单台账!$AE9=1,清单台账!$W9,""),"") -> 旧图 | X8: =IF($F8<>"",IFERROR(MAX($X$5:$X7),0)+1,"") -> 3
A9: =IFERROR(IF(清单台账!$AE10=1,清单台账!$A10,""),"") -> 1 | B9: =IFERROR(IF(清单台账!$AE10=1,清单台账!$AA10,""),"") -> RSD-20260510-001 | C9: =IFERROR(IF(清单台账!$AE10=1,清单台账!$AB10,""),"") -> 46126 | D9: =IFERROR(IF(清单台账!$AE10=1,清单台账!$AC10,""),"") -> 合肥荣事达太阳能有限公司 | E9: =IFERROR(IF(清单台账!$AE10=1,清单台账!$AD10,""),"") -> C型15P | F9: =IFERROR(IF(清单台账!$AE10=1,清单台账!$F10,""),"") -> 组件 | G9: =IFERROR(IF(清单台账!$AE10=1,清单台账!$G10,""),"") -> 4 | H9: =IFERROR(IF(清单台账!$AE10=1,清单台账!$H10,""),"") -> 通用件 | I9: =IFERROR(IF(清单台账!$AE10=1,清单台账!$I10,""),"") -> C001 | J9: =IFERROR(IF(清单台账!$AE10=1,清单台账!$J10,""),"") | K9: =IFERROR(IF(清单台账!$AE10=1,清单台账!$K10,""),"") -> RS10701020216 | L9: =IFERROR(IF(清单台账!$AE10=1,清单台账!$L10,""),"") -> RBKS-300DBII-10-30 | M9: =IFERROR(IF(清单台账!$AE10=1,清单台账!$M10,""),"") -> 风机支架组件 | N9: =IFERROR(IF(清单台账!$AE10=1,清单台账!$N10,""),"") -> 0 | O9: =IFERROR(IF(清单台账!$AE10=1,清单台账!$O10,""),"") -> 2mm | P9: =IFERROR(IF(清单台账!$AE10=1,清单台账!$P10,""),"") -> 16 | Q9: =IFERROR(IF(清单台账!$AE10=1,清单台账!$Q10,""),"") -> 1 | R9: =IFERROR(IF(清单台账!$AE10=1,清单台账!$R10,""),"") -> 16 | S9: =IFERROR(IF(清单台账!$AE10=1,清单台账!$S10,""),"") -> 套 | T9: =IFERROR(IF(清单台账!$AE10=1,清单台账!$T10,""),"") -> 装配 | U9: =IFERROR(IF(清单台账!$AE10=1,清单台账!$U10,""),"") -> 螺丝组装，百胜样机款 | V9: =IFERROR(IF(清单台账!$AE10=1,清单台账!$V10,""),"") -> 0 | W9: =IFERROR(IF(清单台账!$AE10=1,清单台账!$W10,""),"") -> 旧图 | X9: =IF($F9<>"",IFERROR(MAX($X$5:$X8),0)+1,"") -> 4
A10: =IFERROR(IF(清单台账!$AE11=1,清单台账!$A11,""),"") -> 1 | B10: =IFERROR(IF(清单台账!$AE11=1,清单台账!$AA11,""),"") -> RSD-20260510-001 | C10: =IFERROR(IF(清单台账!$AE11=1,清单台账!$AB11,""),"") -> 46126 | D10: =IFERROR(IF(清单台账!$AE11=1,清单台账!$AC11,""),"") -> 合肥荣事达太阳能有限公司 | E10: =IFERROR(IF(清单台账!$AE11=1,清单台账!$AD11,""),"") -> C型15P | F10: =IFERROR(IF(清单台账!$AE11=1,清单台账!$F11,""),"") -> 零件 | G10: =IFERROR(IF(清单台账!$AE11=1,清单台账!$G11,""),"") -> 4.1 | H10: =IFERROR(IF(清单台账!$AE11=1,清单台账!$H11,""),"") -> 通用件 | I10: =IFERROR(IF(清单台账!$AE11=1,清单台账!$I11,""),"") | J10: =IFERROR(IF(清单台账!$AE11=1,清单台账!$J11,""),"") -> C001 | K10: =IFERROR(IF(清单台账!$AE11=1,清单台账!$K11,""),"") -> 0 | L10: =IFERROR(IF(清单台账!$AE11=1,清单台账!$L11,""),"") -> RLKS-300DBII-10-30-B | M10: =IFERROR(IF(清单台账!$AE11=1,清单台账!$M11,""),"") -> 风机支架折弯件 | N10: =IFERROR(IF(清单台账!$AE11=1,清单台账!$N11,""),"") -> 0 | O10: =IFERROR(IF(清单台账!$AE11=1,清单台账!$O11,""),"") -> 2mm | P10: =IFERROR(IF(清单台账!$AE11=1,清单台账!$P11,""),"") -> 0 | Q10: =IFERROR(IF(清单台账!$AE11=1,清单台账!$Q11,""),"") -> 1 | R10: =IFERROR(IF(清单台账!$AE11=1,清单台账!$R11,""),"") -> 16 | S10: =IFERROR(IF(清单台账!$AE11=1,清单台账!$S11,""),"") -> 件 | T10: =IFERROR(IF(清单台账!$AE11=1,清单台账!$T11,""),"") -> 激光切割>折弯 | U10: =IFERROR(IF(清单台账!$AE11=1,清单台账!$U11,""),"") -> 组件 C001 的子件 | V10: =IFERROR(IF(清单台账!$AE11=1,清单台账!$V11,""),"") -> 0 | W10: =IFERROR(IF(清单台账!$AE11=1,清单台账!$W11,""),"") -> 旧图 | X10: =IF($F10<>"",IFERROR(MAX($X$5:$X9),0)+1,"") -> 5
A11: =IFERROR(IF(清单台账!$AE12=1,清单台账!$A12,""),"") -> 1 | B11: =IFERROR(IF(清单台账!$AE12=1,清单台账!$AA12,""),"") -> RSD-20260510-001 | C11: =IFERROR(IF(清单台账!$AE12=1,清单台账!$AB12,""),"") -> 46126 | D11: =IFERROR(IF(清单台账!$AE12=1,清单台账!$AC12,""),"") -> 合肥荣事达太阳能有限公司 | E11: =IFERROR(IF(清单台账!$AE12=1,清单台账!$AD12,""),"") -> C型15P | F11: =IFERROR(IF(清单台账!$AE12=1,清单台账!$F12,""),"") -> 零件 | G11: =IFERROR(IF(清单台账!$AE12=1,清单台账!$G12,""),"") -> 4.2 | H11: =IFERROR(IF(清单台账!$AE12=1,清单台账!$H12,""),"") -> 通用件 | I11: =IFERROR(IF(清单台账!$AE12=1,清单台账!$I12,""),"") | J11: =IFERROR(IF(清单台账!$AE12=1,清单台账!$J12,""),"") -> C001 | K11: =IFERROR(IF(清单台账!$AE12=1,清单台账!$K12,""),"") -> 0 | L11: =IFERROR(IF(清单台账!$AE12=1,清单台账!$L12,""),"") -> RBKS-300DBII-10-30-05 | M11: =IFERROR(IF(清单台账!$AE12=1,清单台账!$M12,""),"") -> 机架加强板 | N11: =IFERROR(IF(清单台账!$AE12=1,清单台账!$N12,""),"") -> 0 | O11: =IFERROR(IF(清单台账!$AE12=1,清单台账!$O12,""),"") -> 1mm | P11: =IFERROR(IF(清单台账!$AE12=1,清单台账!$P12,""),"") -> 0 | Q11: =IFERROR(IF(清单台账!$AE12=1,清单台账!$Q12,""),"") -> 1 | R11: =IFERROR(IF(清单台账!$AE12=1,清单台账!$R12,""),"") -> 16 | S11: =IFERROR(IF(清单台账!$AE12=1,清单台账!$S12,""),"") -> 件 | T11: =IFERROR(IF(清单台账!$AE12=1,清单台账!$T12,""),"") -> 激光切割 | U11: =IFERROR(IF(清单台账!$AE12=1,清单台账!$U12,""),"") -> 模具成型，百胜样机款 | V11: =IFERROR(IF(清单台账!$AE12=1,清单台账!$V12,""),"") -> 0 | W11: =IFERROR(IF(清单台账!$AE12=1,清单台账!$W12,""),"") -> 旧图 | X11: =IF($F11<>"",IFERROR(MAX($X$5:$X10),0)+1,"") -> 6
A12: =IFERROR(IF(清单台账!$AE13=1,清单台账!$A13,""),"") -> 1 | B12: =IFERROR(IF(清单台账!$AE13=1,清单台账!$AA13,""),"") -> RSD-20260510-001 | C12: =IFERROR(IF(清单台账!$AE13=1,清单台账!$AB13,""),"") -> 46126 | D12: =IFERROR(IF(清单台账!$AE13=1,清单台账!$AC13,""),"") -> 合肥荣事达太阳能有限公司 | E12: =IFERROR(IF(清单台账!$AE13=1,清单台账!$AD13,""),"") -> C型15P | F12: =IFERROR(IF(清单台账!$AE13=1,清单台账!$F13,""),"") -> 组件 | G12: =IFERROR(IF(清单台账!$AE13=1,清单台账!$G13,""),"") -> 5 | H12: =IFERROR(IF(清单台账!$AE13=1,清单台账!$H13,""),"") -> 定制件 | I12: =IFERROR(IF(清单台账!$AE13=1,清单台账!$I13,""),"") -> C002 | J12: =IFERROR(IF(清单台账!$AE13=1,清单台账!$J13,""),"") | K12: =IFERROR(IF(清单台账!$AE13=1,清单台账!$K13,""),"") -> RS10701010142 | L12: =IFERROR(IF(清单台账!$AE13=1,清单台账!$L13,""),"") -> RBKS-300DBII-10-00 | M12: =IFERROR(IF(清单台账!$AE13=1,清单台账!$M13,""),"") -> 底盘组件（激光割） | N12: =IFERROR(IF(清单台账!$AE13=1,清单台账!$N13,""),"") -> 0 | O12: =IFERROR(IF(清单台账!$AE13=1,清单台账!$O13,""),"") -> 2mm | P12: =IFERROR(IF(清单台账!$AE13=1,清单台账!$P13,""),"") -> 16 | Q12: =IFERROR(IF(清单台账!$AE13=1,清单台账!$Q13,""),"") -> 1 | R12: =IFERROR(IF(清单台账!$AE13=1,清单台账!$R13,""),"") -> 16 | S12: =IFERROR(IF(清单台账!$AE13=1,清单台账!$S13,""),"") -> 套 | T12: =IFERROR(IF(清单台账!$AE13=1,清单台账!$T13,""),"") -> 激光切割>焊接>装配 | U12: =IFERROR(IF(清单台账!$AE13=1,清单台账!$U13,""),"") -> 点5个电热丝固定卡，割孔，焊螺丝 | V12: =IFERROR(IF(清单台账!$AE13=1,清单台账!$V13,""),"") -> 45247 | W12: =IFERROR(IF(清单台账!$AE13=1,清单台账!$W13,""),"") -> 旧图 | X12: =IF($F12<>"",IFERROR(MAX($X$5:$X11),0)+1,"") -> 7
